# 天翼云盘签到记录

[![签到状态](https://github.com/mfvi/189pan/actions/workflows/main.yml/badge.svg)](https://github.com/mfvi/189pan/actions/workflows/main.yml) [![项目主页](https://img.shields.io/badge/GitHub-项目主页-blue?logo=github)](https://github.com/mfvi/189pan)

**最后更新:** 2025-08-28 10:50:39 CST

## 快速导航

- 🔄 [查看Action运行记录](https://github.com/mfvi/189pan/actions)
- 📋 [查看最新运行](https://github.com/mfvi/189pan/actions/runs/17284332605)
- 🏠 [返回项目主页](https://github.com/mfvi/189pan)
- ⚙️ [手动触发签到](https://github.com/mfvi/189pan/actions/workflows/main.yml)

## 签到详情

# 天翼云盘自动签到抽奖程序

## 执行概览
- **启动时间**: 2025-08-28 10:50:39
- **账户数量**: 3 个

## 账户1
登录过程出错: HTTPSConnectionPool(host='open.e.189.cn', port=443): Max retries exceeded with url: /api/logbox/oauth2/autoLogin.do?appId=cloud&version=v1.1&clientType=20010&format=redirect&paras=8DA63FA397F08DC6E147A9EF130C87CBAAFA8AE63BC2C1514DE979B7776FF21D6D79A13E1CC6AC85316C4D018915BFCD34EA25CCF7823F79CC6641EFD389C4E8B70225A785AAE0CE4A5AB422BC931EAA1B7E8730D149494CEF87DC7D569B3854F9681BEF2FDA9B22BE1E451F2EF20C57DBD56FA947580638E5CB6DFAAD4515F76298FEC928EE69510853A17EE868F82F7512FFAD7F50AD4FA47B3C7F40CB9FBEC5652F42267B3B06DE80F0442559A81AB79ADA057D52E0EA02B6CCBAA024ECFADFA499F2C12B562F06EC33E91A9DA72E5057284B8B709D595643F69A3BA35149392EA0477C958F791D8D4C2B09986395670B319CF119FE4BB5A219710B3ED6FA4C8AFB008399AB015D26C36A7E4D11199B595AF3FE3F7EB427C7BB74BDA5076EEE6649F6CDF516D08909DD562AE1E2C35ED29DA8AFD260CFC8EDCF4BBD9F2AEF86E6D97814ABF81C3955E19A722A0D549348B3EEF09E80492C14EE0A6BBF2C5CC9FA976DE89148EA530802168952E82A8D1F847C7A38E0E2529343E428087D5A05324339A6041A1EA3BBC9240008B1D44F98A6CF2949E6E8A83B27E0D8E09CFBB6E12D79CA3700B36895F37EE402E685CC36C2C864C40107320744BCE50D29067C17A25410F4E8727643ED74506266FAF7AA1994282524E32213D3D2AE8AC819CE23C80E2B7EAFB8519C74A0DEBE981B5B4053831558890B7A2BD5D9DDD123C9628DFDEC185A4E6FD98B1272F1D08ED1556896B361DD02B2&sign=0752749E63E30175372B5D42EAB6B12A5D481F46 (Caused by NewConnectionError('<urllib3.connection.HTTPSConnection object at 0x7f8a3e9e4a50>: Failed to establish a new connection: [Errno 101] Network is unreachable'))
### 执行结果
- **登录状态**: 登录失败
- **签到结果**: 

## 账户2
登录过程出错: HTTPSConnectionPool(host='open.e.189.cn', port=443): Max retries exceeded with url: /api/logbox/oauth2/autoLogin.do?appId=cloud&version=v1.1&clientType=20010&format=redirect&paras=6E6FAF42BD3D4264EA61E0C41B93DB9FBAE132E61D33A456436B8F9CF76EDA44EB7D2BEA3652C1516124B57809953F429D213F422BF5658BEFE382B709C351B56FF25707A54B39D4FE62E787B9E12E068841BA866C7E635533796E141B67524B4C8D221131D1967127A598595DED52C4C8C00953C9802646476A0CC69AEC29E09C5C81BAD2AE71CAE75795ACC0CE65C49FE4F5E651B0BB5A32295374D5DED5CC883C5F2194EF1EE7DC7211FAE10AACEC948E225F0B46E6BFF9A9748FA886B77FE1259FDE05DD8996A7CA3ADB5AC3689F32DF95923785CE298809045DB168989692F0B084FFF7120B0EE96717870AD42458603C2E5B943E94C7237E81109983AEECB4DF42AE716AE5D0A672FE590AE9EEF9070C9E2D3B61A041853B85AE798D1E0DD6A79FF3EC10A2247136EE57886A64F3E14B2D2B1C5A890C586A9A054F8C987A3586DA717A0D6AB75B364D50D598EF21BF2E013F127553DFC11B78391F96F7E8C071C79BE05744D6FEA863C4D476028484E7E771324F7900275C7F94ED4C9267673322483716B767544918BAC4FEFA68925CCA10BBBB2F6BD8330B5C5F89995342B09E3F0831378AF2A01033601F4488DD5661A9146FE8E23A5543C8429923C85469E733895524B89515554CDB59176AD864B64B1F1FE0C210690A92436F0D035A508692ADD58C4FEDC9359577595B8EA6628F85847E328B7BD9FF560B8B8A9661FD01199B782F3391878E049BFD95FB2159E9028F957A&sign=86421906C5D216C4F77190F2414F01F42B7B9F85 (Caused by NewConnectionError('<urllib3.connection.HTTPSConnection object at 0x7f8a3e9ec290>: Failed to establish a new connection: [Errno 101] Network is unreachable'))
### 执行结果
- **登录状态**: 登录失败
- **签到结果**: 

## 账户3
登录过程出错: HTTPSConnectionPool(host='open.e.189.cn', port=443): Max retries exceeded with url: /api/logbox/oauth2/autoLogin.do?appId=cloud&version=v1.1&clientType=20010&format=redirect&paras=E1CF56B56334FC8A517A799254A3640ADAC18A0418230364341D64DB4BF46E168B47B439B9684809E707371D267FCC5FAC79D5886AF8DF3089C673DB3732AEC874CDD533E9898ACD0573FB99E100FA00ECA135C509553D68FD70334330356B9B24C115F2D1E4580D5E9861C82AEAF6D3C1A02EC2A5080C18515D8D1EB14E7C2721525355DC2C229D834826623CE811C90E693A90CFC8D11C01B14A53D2527A3FE99961F6F52B17CBD7265874B856E43E488E23CF02361AA1597F44A62A20C0C025084BE2451BD3E12D89E53A0EDFC36273C55548D42D4043C4D4390227AB170A02DC103C258168AFF187EA75DEDB172D6C4BF0F6577D71532F5F2A3721472E0EF38F3839EB110F29C6C6A69844AC83D997C724500A5B36DF50485829D1186DCAB5DEFEE7618FD749377F079915BD04337E57FA937FA2347EC2064A335D8D3840ABE739067CB7EAA89903E83252F0E6F25E883FFA205CCB959E1373173A43C8823CC0440E6E31212BC61DAB0A901A90640A63131BC6515BADAF8FA0605A15E2154DF00BBA41E19AD900FF3442662AA6E7FC9B9663B886DDE2045BB8E6A1A375695E6D9D1E00EC8820C9585712B64801162FDE576BC5B2E9E40269A157F2EB3042E58B487EF023480A0E474BE6364FF0C61ED8C192AC0B711BF9062F0A2162BAD5F1DBCC08B900DF3E17231C5AE0D2B91F2175BD5DC5091077AC5FB136A9E7F3642F8BC370C5C1636C683CA69FDB577F2825F5F5E96A6F24C9&sign=69BD0762F3B19DD18485DCE92909691FF22E4A51 (Caused by NewConnectionError('<urllib3.connection.HTTPSConnection object at 0x7f8a3e9d7510>: Failed to establish a new connection: [Errno 101] Network is unreachable'))
### 执行结果
- **登录状态**: 登录失败
- **签到结果**: 

---
## 执行统计
- **结束时间**: 2025-08-28 11:04:11
- **运行时长**: 812.30 秒

✅ **所有账户处理完成！**
