# 天翼云盘签到记录

[![签到状态](https://github.com/mfvi/189pan/actions/workflows/main.yml/badge.svg)](https://github.com/mfvi/189pan/actions/workflows/main.yml) [![项目主页](https://img.shields.io/badge/GitHub-项目主页-blue?logo=github)](https://github.com/mfvi/189pan)

**最后更新:** 2025-10-06 10:49:18 CST

## 快速导航

- 🔄 [查看Action运行记录](https://github.com/mfvi/189pan/actions)
- 📋 [查看最新运行](https://github.com/mfvi/189pan/actions/runs/18268585188)
- 🏠 [返回项目主页](https://github.com/mfvi/189pan)
- ⚙️ [手动触发签到](https://github.com/mfvi/189pan/actions/workflows/main.yml)

## 签到详情

# 天翼云盘自动签到抽奖程序

## 执行概览
- **启动时间**: 2025-10-06 10:49:18
- **账户数量**: 3 个

## 账户1
登录过程出错: HTTPSConnectionPool(host='open.e.189.cn', port=443): Max retries exceeded with url: /api/logbox/oauth2/autoLogin.do?appId=cloud&version=v1.1&clientType=20010&format=redirect&paras=5A6B1C3A54419509118385308F955A2E9CFBB4F2D9119951F5B987D600CBE9789E6594608E6188382E253601D0319884E54ADC0B1C1195DFD1B233E44B1F48D0856A1ED3F95D87E6FFC952B717511921381ACCA0E66E8ADF24D294430BDB235AF4DCA4055942D18C91041BF8C0009C197F0887E12514639B01C35626752BC1E3743E86065C9353C645EE156D9BC3330AFEF15054EC034902152DEE2C8DDB5302B17A7DB3C8847F2F5F05174CD453BA7FB4715DDAD033825F95AC801C28CF339191D55C2F75784402ACE535717224856AF8DFE47F0F43B9C05DDB2F6EFC06B4133FA730CF2F72CFF9FF3C1143EBB47BEBCA2B0DE5DCA3E70F23B5358868FB2063ECFF4099A1898364D71993A905BB24664441DE8DBCE7CAD3157140435D2978E49B5ECEF7C9CEABE4A25D39CEDEAA6F962B146A08562F512AA9393F715DED10EAC32D2B1FEA12CC8EC216534DDDE965BD09CED61B14E74F9B74FFF22AA58C1855E1A1897969CE016CFB7640C2737B05EA235C64D1103F7FF3138EB39E4D800E946F1D53C17F013167BC6A8CCE2B40176A5F8C106F2B3029AA88A03C186DAD01F9B4F13C5B8E70FEA8FADDDA4A248CF1B7D099F14E17BC2468EE16FB76ED7D4B2C1889F647F0538E09FB95C2B511DCBC39DEBACD700C7CA944815D0EE6A8624795DEFB361CC819DD8100DF2DA9E77BEFE2492E9857E1D1149EC669E36CE0B1B36732C947517F9F0064BF5EFF179D30E599170395102DE71D4D&sign=D55D10929B7789A12E81AA2D4970740F07D1235E (Caused by NewConnectionError('<urllib3.connection.HTTPSConnection object at 0x7f518dab0cd0>: Failed to establish a new connection: [Errno 101] Network is unreachable'))
### 执行结果
- **登录状态**: 登录失败
- **签到结果**: 

## 账户2
登录过程出错: HTTPSConnectionPool(host='open.e.189.cn', port=443): Max retries exceeded with url: /api/logbox/oauth2/autoLogin.do?appId=cloud&version=v1.1&clientType=20010&format=redirect&paras=267E95E59A609DA6050A80942E552EB1619CEF9BDB2CBDDD5C069C50D85228BA76A99DF75316B356316C1FF745C2F445B53E5C1690651FD2D1D65E884C55D9A23D1126E7D11C59DF7CF84FFB8E31B6D3775FE84199B734EA6301AFF91614FA4348E975C329B5CCE620B6D0F252FA6429DB5DFCC8C5D07B6D7FA710A7D058D824E2BC0062D34EDE6E7AF96E850BCCF1BC9F0C78A67E1E7128F6BA3D80DBB7C9D4AF944CFFBB2B53CC268CC353F121E128D88277A4E97D91000EC69DA160BE5CDECCFBC85CFD19346AB8796AC3FAF5686DC1A9919C018403D3472842F5B11361B61112D3FA439B319F66F0AE69FFB24DE528BDB2C421A4AAC50AC30C1EB9BB6C4A464BFDD1DDEE8B18E2DC705BE9061C5573908D549A9176B740EF127D1F121A9BD056CB6C05A3D46CD5BFFB7EF404D0F0D397DD2751A082FB5CC2F85415ECB53C0F7420198BF593076F70A2C1695D8308907711F93105439D43CE37DA02A922620A714D8ADAAA205C730020709B58B9D74D2CAB91D7AB4B7BA1EA3976B118618C31E73A2AA71FE5C8A0FBF84697E258207D3DD03EA0A83D2CB5C638505BC5048F7DB8A82A67CA0372DBAD84328CC564EBB3D93EA46B918FE405C8CEE77516FF81D8B0409B289D0A41047A64A891702A838881A34E56072F51F6CDC4D8EF2CFEB5ED26F3B60014D1270EE82F64368128040398CE00418B05A0A82C8E764F824AD2B58577A4F48B05B1114029690A4ADE91150135D06C5FF397&sign=D3ACDC9E81C40A8D469F076EEC02E91733E1DC9E (Caused by NewConnectionError('<urllib3.connection.HTTPSConnection object at 0x7f518dab84d0>: Failed to establish a new connection: [Errno 101] Network is unreachable'))
### 执行结果
- **登录状态**: 登录失败
- **签到结果**: 

## 账户3
登录过程出错: HTTPSConnectionPool(host='open.e.189.cn', port=443): Max retries exceeded with url: /api/logbox/oauth2/autoLogin.do?appId=cloud&version=v1.1&clientType=20010&format=redirect&paras=A418B06CBF3E4FFEA85506F6766F22591149C6C9EFDE5870709AA070756EFEB2AC826AF6E5559CF7E48F690038D322AB89120BBECC4DEC08FA8749F659137EA3228A0EE090B198DABEACF33DC5BBEBF36F07BC1C794C6B7FD78CD8847860E149454672974A3E07D3B0D0F06FF6DF423F59142DEA54E774ACF6108E211254F5E2698327CB6BB2DFBD990D56ABBB951FBA38A660077408CEBAEAFA7EEA19B1BE77D44706E5950DDCB96F7B488C318ED6D487682D503C6AB96121C8B5950B1629E006A8B8DC17B3751A475F28FB83884BFB41D24DFFEE64950D03A0A39DBA8381FC3D30E723082D84997914EE1A46B9ABFBB5D5C978034CAFE4DC68EFC8B42409F53004E8C130460308443B1AAFEF10C244724FC85C1EAE38267D9E6BBCA79E1B0AE1B75A3C8BAE09D57E952C371B3D5C91CB31A72424EA3BFDFC11EA45450EB2CAF8FB2990E8B3A840F813A35403DB7C5F8C436A46523D817CB2FE64E2B006B9BE1D4827F3EA22353F5303C4B986D65CB096B70458ACBDD2D8F6D04051B2FAD26F6D749526296292FD6CB17241499CF4CA883F52807F6C5890034779B33C62BD9B3954032C5BB009748E06F69807904191E33FAD03AA478042BD4459E4761B19888355B91B5F59282B053827939D489D9042D57D57C07AFCEBEEBDB1D8E0858FC0299B27B12BB56246BEFC86E9393B98883B9F207F4A9680CA65292BAFEB17D59912CA20047E7867642F9C19A11D3AE8401FE99CA701679F8F&sign=0EB2A3E6C60298F5E3A52ED17AC6C67194AC921D (Caused by NewConnectionError('<urllib3.connection.HTTPSConnection object at 0x7f518daa3fd0>: Failed to establish a new connection: [Errno 101] Network is unreachable'))
### 执行结果
- **登录状态**: 登录失败
- **签到结果**: 

---
## 执行统计
- **结束时间**: 2025-10-06 11:02:51
- **运行时长**: 812.54 秒

✅ **所有账户处理完成！**
