# 天翼云盘签到记录

[![签到状态](https://github.com/mfvi/189pan/actions/workflows/main.yml/badge.svg)](https://github.com/mfvi/189pan/actions/workflows/main.yml) [![项目主页](https://img.shields.io/badge/GitHub-项目主页-blue?logo=github)](https://github.com/mfvi/189pan)

**最后更新:** 2025-08-31 10:54:08 CST

## 快速导航

- 🔄 [查看Action运行记录](https://github.com/mfvi/189pan/actions)
- 📋 [查看最新运行](https://github.com/mfvi/189pan/actions/runs/17351667779)
- 🏠 [返回项目主页](https://github.com/mfvi/189pan)
- ⚙️ [手动触发签到](https://github.com/mfvi/189pan/actions/workflows/main.yml)

## 签到详情

# 天翼云盘自动签到抽奖程序

## 执行概览
- **启动时间**: 2025-08-31 10:54:08
- **账户数量**: 3 个

## 账户1
登录过程出错: HTTPSConnectionPool(host='open.e.189.cn', port=443): Max retries exceeded with url: /api/logbox/oauth2/autoLogin.do?appId=cloud&version=v1.1&clientType=20010&format=redirect&paras=8B908A199CC6BA370CE29972CAD629419EC1A76E4F00573A6006FFF79975B31CF89B2045A31CFF9EDD4CE49C47DA81741F4DAEC851F19BCCF02C7496EDB013BF46577FB2E1D06BDA1314870A7CEBF2DFAC84CA386576A4C3A788A17AD9C203C56100422BC24B66A7668ACE9398F6E9EA63CE201C481A571786B3A45FFC0ED312C156E82EE33E791C69AE6A782A48C7766C800266D2F8605A5ED7682EE278C3A5711B9C9DE507E6D6529206E98A24E49E535969CC778E0A398F50C89AFB3CF4085BD72EE95AB90FB175402697FF512401EC98F02068B67EAB2FA97C5C3518F62B4C0EC754370FE822E096C231CF10909769E52086F3AB2C2B7ED094BA613EC591DE9E92DBFD8C2D3FF2A37C50685F5EA8EB513CB14FF060B6031B9674789B7680809C88B8E46EADD6D2041092722FB2D83BC142CCD38D18F98AFA2832617BD1BCD8E6FFFFCB6A87F00B12DF155DCD9904756F205E85A87F6CBAA2926BB4638866B9B51AE74F1F375AD5B9D82EC7D321E5E4CA82F4B182CB5EDD142976D2F071D57D4B38799AF57D9A704BE5716A0D52ED40749EA75DDF03D7970FD2AE11CE411AC5715BE711451E0C66E5C5B832CE1BE6518D644B0FFB736331CFAB67ECF14A06993BFADF1197F51A124A4174301B5FAEF205FFD6D8311A2A634DB6F9121BAC1EDAA96B79AC1B089FBFA7C1F91D228BF7511A1CFA07B1E14F873496DA4721DCECFA88C04BE673AD242F7B0EB763F051677DBD74A904C1B546&sign=9C9B70F60322875D59A2700DA103FC6E20B4DBB6 (Caused by NewConnectionError('<urllib3.connection.HTTPSConnection object at 0x7fd357a38bd0>: Failed to establish a new connection: [Errno 101] Network is unreachable'))
### 执行结果
- **登录状态**: 登录失败
- **签到结果**: 

## 账户2
登录过程出错: HTTPSConnectionPool(host='open.e.189.cn', port=443): Max retries exceeded with url: /api/logbox/oauth2/autoLogin.do?appId=cloud&version=v1.1&clientType=20010&format=redirect&paras=8349AB0A5406FF1597D61FAF4C4CDB7995E20DD9A65C58B38A27AB2794977618176918C6589B0F9034025EF2E102CA6095708B362606BDF6058E0D49829F6DE370F0EB6D9B199FFD8828AE6183B86BA801A082F3FB124F4D2930F4CC01F485B0D779FB7646400ED286FEE9082DE0219E4EC3D4514D64F82A4D77256DB236D210800E0492AC78B490554D54877FBC8BB6E9EB3DE11A1747E81789B44951641E069BB88AEA6C2E3D9F29DDD70FEE1542EAB3010B69A05F1CEA6B6E53626C27D32D7DABB2814D82D7282EFCD75DB4902964C6F887801C443353C3F0C10F0BCB85E7055BEF5020BF413E32F2DB9ADF29B8BB5A5D7CE67431BA2F2B4E7074E87E744D365749130684505EF07DAE2A57D7078A0C0F5897CFEA0B38BE6826AF38B8E9DF767D932C37638E0383339B011B1D373A2A25A7652E7706D93C487B22D3725DA078EA15FCF436781FF30B58B6AB1B0A18FFBD46E4D0086076FF33202597F2F52E3AF06AED0AA4478440524A4C8A752887AFDE2CE9960C5456623F0E9DBE6C363409C8DFA71EC343A4F8B659455013FF2DEB78FE3F97D0D23C5A37065A167B0C5D0D8E2DB510B083A6DFDA6F9A482321E74D3E4F68BF11B62324BDEAD313BE7FC319472BCA2053DAB25B1CC6F5C4E2D68A89A2D0D1B3D6803365990A948A5E27DFD466ED3992ECC591130684D556BE45341208880CA65B4194FD2A857C968135275BD1EE3705921A0762E4D514D9BACE3B4A47A29D0B6F1F1F&sign=4FED54424D82C31A5FCC0E4C5FCB4E2F28A475CF (Caused by NewConnectionError('<urllib3.connection.HTTPSConnection object at 0x7fd357a403d0>: Failed to establish a new connection: [Errno 101] Network is unreachable'))
### 执行结果
- **登录状态**: 登录失败
- **签到结果**: 

## 账户3
登录过程出错: HTTPSConnectionPool(host='open.e.189.cn', port=443): Max retries exceeded with url: /api/logbox/oauth2/autoLogin.do?appId=cloud&version=v1.1&clientType=20010&format=redirect&paras=909540C3545D33A7DEF78D7206354FE9511DD028056D51D781F51391CE6D8311F6089220F09113248B66954CE0A1AA9C84F0BC8BFF60F59E810A016B31843B65409C861EFFDD9CEBA87C727D3914780890ABC9DE4E484DD19D5B01806AD2BC8FAA63D31ED5834F7747372207F87C5B50E5BFD3FA2F98F176F4269D2DE63D3362A5DF92CD9A96411BC8131D68AD1A77B58C2E8D60D1CD4D21689F1173F588659C50BB12D7AA09CFB4EA1DFF302B05EDB8C84BF1ED7C9DCB5E61A04DCE6E2B7B9C1E1C724C9DA2F4CB57A597451CD988F33A19E54D26C41559120AAAADFED1BE09A41FA4B9FC6201905437AB2561AAE692526EC8F4A476AF50750E0E4218A42FD37CFCE971964905E521A48431FF65BAF593E9520A2D53FAA0D8F414E11261217E54C34D935EE1017D013B0FFCCC19A077EB981CF29D902331573618713C95D23F7F969C1BC487AF1998A88D714BC067580E8C5DAD4FD77FC90E5722F3D543AC21D0F3FCB5D322A1E1126226B7FC72D29F8BE7A79FBD6C52282633462037E99D0037880BF7E82B837AE9D41046D7F500D1CF43CE5F94DEAE969E67F1F88FF33A837BCC02E4F4D901DC0D20FADB651B439CE2E81B58F486097431AA993B733BB0E5F6022C46E5060407D5639ABCBA47AA9C01A28DC33BF358AB96A1B2B5C89DDA58E61F7EFC338CFA88FF01CCFB3938BB98995A7DE3A844497449D437E0E34C12A832329EA680F7BA4FA007C195060C3C8C4CA575CCDF15A49C&sign=BCA642A08A6E7B015426CAB7AE2855DA3E818F12 (Caused by NewConnectionError('<urllib3.connection.HTTPSConnection object at 0x7fd357a2bfd0>: Failed to establish a new connection: [Errno 101] Network is unreachable'))
### 执行结果
- **登录状态**: 登录失败
- **签到结果**: 

---
## 执行统计
- **结束时间**: 2025-08-31 11:07:45
- **运行时长**: 817.07 秒

✅ **所有账户处理完成！**
