# 天翼云盘签到记录

[![签到状态](https://github.com/mfvi/189pan/actions/workflows/main.yml/badge.svg)](https://github.com/mfvi/189pan/actions/workflows/main.yml) [![项目主页](https://img.shields.io/badge/GitHub-项目主页-blue?logo=github)](https://github.com/mfvi/189pan)

**最后更新:** 2025-06-23 12:05:18 CST

## 快速导航

- 🔄 [查看Action运行记录](https://github.com/mfvi/189pan/actions)
- 📋 [查看最新运行](https://github.com/mfvi/189pan/actions/runs/15814965258)
- 🏠 [返回项目主页](https://github.com/mfvi/189pan)
- ⚙️ [手动触发签到](https://github.com/mfvi/189pan/actions/workflows/main.yml)

## 签到详情

# 天翼云盘自动签到抽奖程序

## 执行概览
- **启动时间**: 2025-06-23 12:05:18
- **账户数量**: 3 个

## 账户1
登录过程出错: HTTPSConnectionPool(host='open.e.189.cn', port=443): Max retries exceeded with url: /api/logbox/oauth2/autoLogin.do?appId=cloud&version=v1.1&clientType=20010&format=redirect&paras=F3B2E23CC1A322AFBB00DAEAEDC3E362AEB97A8879091401814FAF3CEF7D2CE4DADF4522E4B3A2E4589C47C37BB861A2721A5BA16B8850A8746017311AD75F17161F57829CAC944F5C82C1049F51A0AA8A18BAABD9EB6E79291B78ECE42EEE5E937163D2B308BE4C9FCEFB3EC6097A46B449797F63F11C75050BD72E202E2D26D98C013312F8F429BDE4070EE1A9C274E89E310F90F517C45179A57E07603537AAD1EA47E1B6447BC1F5062EF9C08BE69BECA287A50216992F6C6CB1CEEFB8C451A1E051D9492E00AAD0DB66E939BEBD0F92919A489D68AA066AD4EA10876BDD90E114B49A4F72428E5CC2F24B41D15590CFF73D58D2659EC6BCFE2F66E24EC4B01F84CC5EDD5D0F3DADD751D95A0BD756219C23E112A1D92C835C9AA7B4BC9BA37EC33395FA5286D3F7DBB27EBD10699CF457B74145657513585A95E3C3A33353D2DF9F383FCD08B69160FBC14D7368AD999482BEF573CBFD086443A3DE8D046CD7E8CC30ED887F6C83628CDD59C373A77E28D9009B5D18E22C79D5539E4DEC0577ABF0833446C2D279C5F4AAEE62B29D50A2FB6DFF090ADB447CC6D7527976C0EAD5A9BCA92D127C69030BB974350AC4AF8C3B97234DBD49A3F38865CA8E03FD1FA0EDBC3177EDF101A485E029B82318641CEC0A8EB46B1CFCF71407126338866BFE9FA95ECF8DB2CB21A7C559DA9B4D389A2E45C60913A528B5D878C93A2439F737DE60A35895683F24ACE726E1E184204D2EA9356867&sign=30E4E95677A69A6C76BB1E0856A8AC2048BB3CD8 (Caused by NewConnectionError('<urllib3.connection.HTTPSConnection object at 0x7fe8da7487d0>: Failed to establish a new connection: [Errno 101] Network is unreachable'))
### 执行结果
- **登录状态**: 登录失败
- **签到结果**: 

## 账户2
登录过程出错: HTTPSConnectionPool(host='open.e.189.cn', port=443): Max retries exceeded with url: /api/logbox/oauth2/autoLogin.do?appId=cloud&version=v1.1&clientType=20010&format=redirect&paras=BA075FF08877B47598522183B8D6F44142D5053C5FF4FD6561437F9A5AEF9CA8B714ACBF9B34871DF99DE39E9514B67D9E7D21D76444982882A29FCB082E6E13F0A2FBC7F53537A841A61FBAC71B98A97D1D68A3C85C5DC4C91D0DB39BE0787F26135149905BA9A183B8885E20FD6B39080EE0EFD28605736D53574B47DDAF293F42AB34E6B16077DBF67FD5FFE2FDB0411E82055C3934A93CE807E52DD3445DA107CF766BA2C53AD8DB935A0E16CB5064405FBAFB840A77278EA6DBB4C85EA093DE05F86664B80007169DAA8D5A036E905174D73EAF7C27757342F3748872321D26CB9757F570BBD3769B8A9CD35487C0164917A58A448FF4613253EDA56B0123524DC0BC7E535ED4DEA9B2238AFC03DD12142463AA71704FD24A9FCDC5A24BD543AF38E15C74F03D322A459986E09FEBCCCFD7BE49A28652ABC8D118664B1689C137541C6477B0845E6EEFE0DEE571F639A9A2FF78535C212FD92B68F7F71853C4F24D2A3F4B8BF6FA5AA1D5B0B62C58CA1556E4BE1D9B033946CC7D1483798584B933EE3ED4291F0CC5AE037F5ECF6403AE98DA9025E0E86BA0AABACD0FB1AF85049975D85560D0E9456CD8B59DAAE0ED9C32DD6CB1BD43CD9F78DDDF5AE4EAD9D5C77EE3FCC5BBDEB0B051A782AA0C2E85A686299F8DF14EDD60640C4735AC12955DE66B13BD60E4A9DAE5F10B8284FFD037ED6A7DBC2FEF0B96C49BCF5B2ACBEEDA93B5B93A56DE98578374BB8F969CF07981CF8ABD&sign=BFE327FAC2D131D61F32DF3231868158B9E4BB57 (Caused by NewConnectionError('<urllib3.connection.HTTPSConnection object at 0x7fe8da74bf90>: Failed to establish a new connection: [Errno 101] Network is unreachable'))
### 执行结果
- **登录状态**: 登录失败
- **签到结果**: 

## 账户3
登录过程出错: HTTPSConnectionPool(host='open.e.189.cn', port=443): Max retries exceeded with url: /api/logbox/oauth2/autoLogin.do?appId=cloud&version=v1.1&clientType=20010&format=redirect&paras=53FEA2001B0EB2231C5C306BBDC0042D2299826152A17C2AE70CA241C1E9781783E40822703AB818BDE31DC17242588C3585D6CF5AFE9D420FF0D3FC92010F7943111A5556E38FA78549497354A37BC4BA622F4B9F85C0E25FC15499DA69CC41BF91E1ECB67E8E832C0195179DB555092674E243362BA621951C4A36AF76815816DB80A163CB19F0494F27D832E84758527BD02858822C79E5A6DBE35589DC5A7E51CA52ADF078C0510F2DFC3171D47C6033866DABEB8E1086CBE7BD934016993316ECC64D443545D5E90974A3EED0805A1AF1312E4B676EAC46C43ADF432DE48C17D760C7341ABA2463F50943D3D311EBB56DF7C1B1B2602DEEA5DEA9DA1A7C15233CA2DB886108A1391355FF7C64659260EFCCCAED910E98454AC433640A3BCD842ACA7F4098B01376D0A32E892548974F82E3206DF372D5F58669DD32FDFD8201C8EBF3B358A77F76C7EB3D69C65883D575D4F1DC22A0567B33DCD364DB3100415D47CCC26BF55FABB521E987C807D6AA86C0DA5D20398E6338780DAF92EB1D1C3D9A0B87E97A6A12F8870A979C0A887B68969FD00B754D09F5865328E5B4BBD19A29C5BD1B6B796B87238A2F0DDE36753EC540596F808BE523A9C9932D013688B71944D7E06581E2CAAC1092B156DE41CF4DF87E08FABFB066CA60A33516E13EA2B7FBCBC3B488163D2327CBEED38A016BB915C74DB2EBD01BC386CC1FA5EE27A18AB539CA98B16EDE4F335DB243711A2A8FDE3EFEFA&sign=B100573C858452AFC05C9BB0D929F0F539601675 (Caused by NewConnectionError('<urllib3.connection.HTTPSConnection object at 0x7fe8da737c50>: Failed to establish a new connection: [Errno 101] Network is unreachable'))
### 执行结果
- **登录状态**: 登录失败
- **签到结果**: 

---
## 执行统计
- **结束时间**: 2025-06-23 12:18:50
- **运行时长**: 812.31 秒

✅ **所有账户处理完成！**
