# 天翼云盘签到记录

[![签到状态](https://github.com/mfvi/189pan/actions/workflows/main.yml/badge.svg)](https://github.com/mfvi/189pan/actions/workflows/main.yml) [![项目主页](https://img.shields.io/badge/GitHub-项目主页-blue?logo=github)](https://github.com/mfvi/189pan)

**最后更新:** 2025-09-25 21:46:17 CST

## 快速导航

- 🔄 [查看Action运行记录](https://github.com/mfvi/189pan/actions)
- 📋 [查看最新运行](https://github.com/mfvi/189pan/actions/runs/18009575171)
- 🏠 [返回项目主页](https://github.com/mfvi/189pan)
- ⚙️ [手动触发签到](https://github.com/mfvi/189pan/actions/workflows/main.yml)

## 签到详情

# 天翼云盘自动签到抽奖程序

## 执行概览
- **启动时间**: 2025-09-25 21:46:17
- **账户数量**: 3 个

## 账户1
登录过程出错: HTTPSConnectionPool(host='open.e.189.cn', port=443): Max retries exceeded with url: /api/logbox/oauth2/autoLogin.do?appId=cloud&version=v1.1&clientType=20010&format=redirect&paras=C7B8C9D5477D1AB0843DC8AEC0C9C724983C206CDCDC8E55D96845F9E44466AA589DFE1CDCE133DFDDD7F012C5EF2B3D2CEFAEFC6E101CE3EA3B4D8E2ABDB9C6E402BDFC1E981C3205077D2EB7221F07CF90C2D57970E045D40D37E887812D1D708227217AE2B50D31AE3250606AB694F0C2EEF37CBA7BE1CC81FB4B415D2671DF53C9B7EB05C881B1D6ADD7A613E368F1972AA893CE780AFC1514399FD08A5DD9C279E18A5796CE6E33D901EB71C63EAAD95FAE13A8813B5E52EF3921847CAF722CE6840811C2E92E1CFA06DBB829CEF56DDE6FD3A397D8E243D40B62198C7AFBB52F0689713D7426A704E1B7F310C60860D8DD9F0F83D89CA5907447A2366CD7BBE64452842040AD34962802F77DC784659B0B004F88B6673CEA5ED8D3647717BE6F28F41FE942E99B0B4F3B2A46AC970819760AA4ADE9D4E53F5125AEF451A287D1BF8B1831BDEF404C2EEB8331E8DF4E187B4F3858DC1030B9DD9BB78F97C4551CFF05DE8CBC677BB1D3ECF3FFEEBD6823DC24769DD8F20462DECCBA768A899C32BD5D7A5DBC8B026A4EE1B98B5AA6615D3743AE838DC03EDCBC8CE71CA45DBD725E9E8F4BF9FDCE53D4A067C8566555E5C7048CFFF1718CC6CB3B5C61284ACD0C081EC8E7334B82CA118630232964D79EF0BEB30E1FD69E5167D84E6BF76DBFD49F4BF847B78EE20BACDBA3A9F3DD6AFC8BE33F9186B5692EB61CA562DC742602665E32E587ECBEC269440CDCA50BA01A735AADC620&sign=EF76BAF34BF623B456698EC06254F41837F99FF7 (Caused by NewConnectionError('<urllib3.connection.HTTPSConnection object at 0x7f30804c4ad0>: Failed to establish a new connection: [Errno 101] Network is unreachable'))
### 执行结果
- **登录状态**: 登录失败
- **签到结果**: 

## 账户2
登录过程出错: HTTPSConnectionPool(host='open.e.189.cn', port=443): Max retries exceeded with url: /api/logbox/oauth2/autoLogin.do?appId=cloud&version=v1.1&clientType=20010&format=redirect&paras=447B03C9A49EB51905E3A8F764271F2D7AA28F24882CE1F8387F3558E9AA4D2BABDD0ECBFFB5779A80D07CB022A0C514627FC8507179286891073992242933FBEB2668A2B257B66E0ECAEC1B8A732C1E6E6818013822194F1F6C8C46E3E7CF21F41F3BF64CAB956B04A4C73C4312D6DDD47179A06C7A6FDBCE966B4B1F7BCD1B323E6D19ADBEFB8E808BE343021EA4FE4901F44701C72522A7F1B2186C14C4E2C236ABF01FD79FF74E194A8596C2906A0A5FAB358FAD394A550B8E2C4BE92CEA553554BA4E0B8B9AB3BED252CE270B46DE9D86BB567A27208C8C9D2AD2C22FB9B512FED7F3B1D7283C8E718FE76BB43E7DA50B311B878D9E8714F4FE85ECA62F0A6703E257EECDEB05B0731B206CC91AB3155F59281C8785E68BD73B234E2C8C8D077C24C6B4720FB7B3DBD68FA6482F2304E54CA30ED0656EE567964C36B532B3AACC117BB5875F74A1CF073642FFADC52004D8A186FDA89491DCA87323F977593BA15002BC317C9FC65DFF985EC1A03A707E9857E7B450C5D25F015B5F805D4D2878543131C2A1912D97629E21AF9A4D06844D94D64DFAFD86A5E3893FACE134DC76F64DAA89F60DFF60E537BBC0C94FFCB8A73F302E6573796A45EF456AEF5E30C1BE2A36464A9DD24356B2E2CA19C62F5AE2BC560B99C04346643996F910346D5FD99F98E6F92C4460E3A3F135BCE87C8C569EA65DA7EB7A4109595E270EDE62B67D311F66899483AE2DAECDFB56E7D0E7D41443E6D1&sign=936273491AE56ABC09CC62917035F53DF6255B5C (Caused by NewConnectionError('<urllib3.connection.HTTPSConnection object at 0x7f30804cc2d0>: Failed to establish a new connection: [Errno 101] Network is unreachable'))
### 执行结果
- **登录状态**: 登录失败
- **签到结果**: 

## 账户3
登录过程出错: HTTPSConnectionPool(host='open.e.189.cn', port=443): Max retries exceeded with url: /api/logbox/oauth2/autoLogin.do?appId=cloud&version=v1.1&clientType=20010&format=redirect&paras=0FF08A874432B4FF94221B321418E0EF2E5C777BEE9920A46D9EF8C7A97B467C35F35754D2E62A262F17BACF011B55FBBC993685E3C7B6BEC4352AC6326662995B500B974CA06A6E4B124F2EDD9431436F33AADA989465AC33E9812F1E54E46728C3F6C62884D6783FA91D989B163D707B2A67E0BC163CBB1D7AB697CB87D70D47DA3DBF4FA7D9D361E57B993383C9E8490A52D2AB583937ADD216DA55DB6E56FB262C57B26ABFEBA44CC4AD640DD99A48BF7699B8479053F652B3C038EE0F071A927A4AE4C5ED0D8AF33200E0BF23FDD86FCEE74DC57DE1476E1C65EDA53D13166505860DF68E7879977508BFB77D1455F2B5AD08EA25649454D8641A6985CFE1213889924049698192FC651D80E08DD5A2720C96CC6735C7FA51AF0FF96E4928DF030CA9D2012B3A011FF4AD601107897F43E6C99362D82B234E8A204005873F1D73605465C0B85FDC8A394352EE67933F46CD6AFFE8182B1FB67AE3C1B35C6B05872C22A9BF3E8BAB3919C3B32B2D46A3FAF41906E8FE4F69963BBEF74700DDB7A11CFE01F50461F872F2F6A817A50909D62F1E23CFCEB42A5CE083F79BD632331DFE59E853A7FFCD2CB09D76932EE1BC5C1E75A12369B46BE50E35581D6E1EE1A82008165EBDD994D05BA16E52A4393DA9C4FEA571EEDFB958379CD5982DA2817C5ED2D78DDEFBE110F04683FE051AFB9A66F32F38C7E95238F675A33C86088B37B2B8A3F4A58CFBF5BC3F45D837D8B53B8D74FDE073&sign=3712B1E00D89A56625AAA3FAEB220A7DD2AA45C4 (Caused by NewConnectionError('<urllib3.connection.HTTPSConnection object at 0x7f30804b77d0>: Failed to establish a new connection: [Errno 101] Network is unreachable'))
### 执行结果
- **登录状态**: 登录失败
- **签到结果**: 

---
## 执行统计
- **结束时间**: 2025-09-25 21:59:55
- **运行时长**: 818.03 秒

✅ **所有账户处理完成！**
