# 天翼云盘签到记录

[![签到状态](https://github.com/mfvi/189pan/actions/workflows/main.yml/badge.svg)](https://github.com/mfvi/189pan/actions/workflows/main.yml) [![项目主页](https://img.shields.io/badge/GitHub-项目主页-blue?logo=github)](https://github.com/mfvi/189pan)

**最后更新:** 2025-09-28 10:55:18 CST

## 快速导航

- 🔄 [查看Action运行记录](https://github.com/mfvi/189pan/actions)
- 📋 [查看最新运行](https://github.com/mfvi/189pan/actions/runs/18068353460)
- 🏠 [返回项目主页](https://github.com/mfvi/189pan)
- ⚙️ [手动触发签到](https://github.com/mfvi/189pan/actions/workflows/main.yml)

## 签到详情

# 天翼云盘自动签到抽奖程序

## 执行概览
- **启动时间**: 2025-09-28 10:55:19
- **账户数量**: 3 个

## 账户1
登录过程出错: HTTPSConnectionPool(host='open.e.189.cn', port=443): Max retries exceeded with url: /api/logbox/oauth2/autoLogin.do?appId=cloud&version=v1.1&clientType=20010&format=redirect&paras=B2883D383818122F1A0F29AC4CAA21367E8BB7007A89000867DB2769C2ED92150B7E69305A9822546CF34CC97DDD6DD0AF5D873DDF02646532B147BF8DBF6F2271A739BF4EF140C36BF9245A042798F1B06A7DF8A4ACF795747853EFB58B6E8B3D801F6F05539DBE6661B0211D504354470FEC9E0277DC879E7657E2F75B4A0219EF166B309FE1ADCAE28962F90188C12D7285F3BAA3B39EAA5B8DF1C67AA5933945285D3CAB29E0262DE7414CC296DFD46A85011B70B9D41DEF11EF501876FF1D26CE7D21486F6ECB7EC8DF3E071573CEABD81CC5EE454A8BF042058EBB8CB87E975315B52AFFD522C3427DBD125D9AAFEF05BED6E01412813F23FAF834C8FFA9483581308D041B102A156F6773376B35C1770CBFD87E87B7ED88C589A0C55B5E4E0D4F08627163C9181511C3F045F8002E3A07F76A3192D65B8C2DCA6F285E8EEED2B951582A9090486F1EFE12F8CC3D7BB4F299499FAFA26A409D6C277A32E8B877438811EC0BA84881D5D591CA0E112DA08E8D2A33BA9DD2292302C8CBC70182389414D18C183893C314AF69F7FDE03E8152FD2F561F3232BCA11EA5CFEF5AFF51990406B296F196334A425DE9FA18B236E2E875E25C9D878DF293EA647A09C390082E7E057CAAAF7FCC6582FF5254A7E0CA77203E8D64085DD452843557FF739C140DBDD90414A1F5C877911BAF038514E19FD66559F45236BE71A2852BDE8FFE0F46069FD94E780DC270408D26A6A0DA60BEB202E8&sign=29F891F404F08729D679200B2C43647A4B0C5ED7 (Caused by NewConnectionError('<urllib3.connection.HTTPSConnection object at 0x7f0042568d10>: Failed to establish a new connection: [Errno 101] Network is unreachable'))
### 执行结果
- **登录状态**: 登录失败
- **签到结果**: 

## 账户2
登录过程出错: HTTPSConnectionPool(host='open.e.189.cn', port=443): Max retries exceeded with url: /api/logbox/oauth2/autoLogin.do?appId=cloud&version=v1.1&clientType=20010&format=redirect&paras=6A62BF8016400936E0E23237E19293D129833EB127C59880E8C3B7F695C27F8039FB82844BC7595397D2C8C01191868DFC2073EABED79F25933EB11D2C9A56188B57ABC7E1EEE2285DC9044C320BD3196F0906FE9BDE8B25A4D797723074AD40C0F255AA7A708BD8F1A5841EE802485FB2133F2F0CDC84F96999D196A88DCA0389BFC04178A37DFC82134FFA0158D398AF9D98BE85B13305F65E4F3924D8852817905CFCFEA4E4E321F22E023828DB8F333882F4720F52077F1DA802D57E6F8B04C4B9E48B8B3EBE361CA9FD42566B6138466A2A6418F1548A8140AFC6AE148C31F2440A1B196F913A9111F132185E9223C1F32AC48D3E0AA12B96BADF1D184B9C41B8C37FD63E61467E0F7A981B29A8458B099AA9182BFD89AF483E52FF1737A3CC6C3822E71E7B79AD879AF1294C6A4978A1199B90B5BC84FFAA95D7C74D4E53AD29E40CC3F4FA5F7A234B762AD08EE5E15D454EC2CD759943FE9DB0DACBAFB6AEC610DDB1767CD28D139042659B8FAD25FBB2040760D63C0545E01322A5C92B7821F4ED1896ABDF3D7638B97084F932B148CD2E13AA4FBDF85B0B445B98F232E5D2E653F74E59FA4C97AC6B0ABC087AB3370AB4656DB64B02E893AFBDB9C02E8B310E9EB460A3E0E0871314333CF4B219D062A8BB656AE3A71C788EA211C086C59CF1D2BCF149B17767F029D3FF37D0DF298FD0408A9E3F7961743F56AEBCE18CB121654C6E75CD8A2C4C3ADC4279FDBB01B0C7C6DD01&sign=B63663A187909F91B3CCA3AECA31265E2D76291E (Caused by NewConnectionError('<urllib3.connection.HTTPSConnection object at 0x7f0042570510>: Failed to establish a new connection: [Errno 101] Network is unreachable'))
### 执行结果
- **登录状态**: 登录失败
- **签到结果**: 

## 账户3
登录过程出错: HTTPSConnectionPool(host='open.e.189.cn', port=443): Max retries exceeded with url: /api/logbox/oauth2/autoLogin.do?appId=cloud&version=v1.1&clientType=20010&format=redirect&paras=5C391733F060E97670B12A05A9BD0CA388CBDB277F59854AF6DE8DD828C85245F347E07928E583366029323E7341D66A5B4EBA153370EADEDA1CB3BFC655FB7E0FDE677805E408A6388EEEAB506AC90DF72B102E99E381C36AA3D9297E335EF44E4998F0DED2656916B1753D8795E091B7DF60842F6D6998A82C6D18D491308A50C39E70D3E48CDE7E1BD448FBDAD83518F518A334F28A448FC6250BF88816F673DB2ADAEE2DB514477A44A7209FA42D272C1088DCD76637384C4D77D38B2EEF41A12EE8A4E2A738498284E8F813E44E985CE2E2031F421514C76DABED53B4A1F1587A08E9D7F4343228B3BD6617E14B85B8A260379AD94A71FD35730BA969EDA079DE89D113DF64379F6210233E8FAD32DE0495E56DB6A069A1DC63C6B7E39C12992F25504B15F26B1DABF7C6C8654D60E1C97C457C15515A88AE58880425AF01E85559FFD097F0BEDA02C090339A66116099C2ECA4E6C5F8E8B74FC5BFBD10B654470EB1440C5DF57B44A84F7A5B2B20981E9F1A7D8B58D7378899AC2CDB0E9E10EE81902A554D15413373957A45E6828820580F003F9D9A856E59F9F31A579AC3225A49ACFC9F14BE626A702CA11B744F4C0A6B1A2B8D95E0301C653EEF7A1233E35398E3D0A76CFDB4B350601A12C0CAFFD925FB80E8C1DBA20F30AE57F416BDAF6F32F74263D0D69387CD59F75F9644A5A0A31715B24F0C68E37C8A4AAEA6A060ACBA485AA636B591842E3B6C9727170747E0A73EB5&sign=3DE7483F71592F0C98CE79A7F95D34F90CF642EA (Caused by NewConnectionError('<urllib3.connection.HTTPSConnection object at 0x7f0042559b50>: Failed to establish a new connection: [Errno 101] Network is unreachable'))
### 执行结果
- **登录状态**: 登录失败
- **签到结果**: 

---
## 执行统计
- **结束时间**: 2025-09-28 11:08:50
- **运行时长**: 810.97 秒

✅ **所有账户处理完成！**
