# 天翼云盘签到记录

[![签到状态](https://github.com/mfvi/189pan/actions/workflows/main.yml/badge.svg)](https://github.com/mfvi/189pan/actions/workflows/main.yml) [![项目主页](https://img.shields.io/badge/GitHub-项目主页-blue?logo=github)](https://github.com/mfvi/189pan)

**最后更新:** 2025-08-10 11:24:54 CST

## 快速导航

- 🔄 [查看Action运行记录](https://github.com/mfvi/189pan/actions)
- 📋 [查看最新运行](https://github.com/mfvi/189pan/actions/runs/16856737135)
- 🏠 [返回项目主页](https://github.com/mfvi/189pan)
- ⚙️ [手动触发签到](https://github.com/mfvi/189pan/actions/workflows/main.yml)

## 签到详情

# 天翼云盘自动签到抽奖程序

## 执行概览
- **启动时间**: 2025-08-10 11:24:54
- **账户数量**: 3 个

## 账户1
登录过程出错: HTTPSConnectionPool(host='open.e.189.cn', port=443): Max retries exceeded with url: /api/logbox/oauth2/autoLogin.do?appId=cloud&version=v1.1&clientType=20010&format=redirect&paras=649E67EB8CCDBC0B3161EDE36C8211593DE7405D0C5295AF9B921371F04D53F4E5FE5EAEFA8B7ED86037BB33F1D8CF115AD5397FCF971A452000EFFAEE444022C2D775176F5107C07610BF4D9A3DC43B9A664B15DF59D18764B48038787DA1C79709783997335BCEBE4E63FB9086E026F108E445FBA9AF663DAE27DE9A46DF06E9C8FD6AAC319319A2725A6407D75476C3EF0FB5C202432D51205CB2A493C8111A477D98F90292330717D308EC7E0F79197BC8C5B609087E1513E33809041A054DBAE7620A3F448540E61680E3D009C1285C3B304F4491F25BE366DFA0FBA2DD9D68EEE987F41DC51E3D8889AD44D58E2234272DC08265CB4E24BB0B9716CC6C4F41F1E10F5CF9A3B20C20C577DBC7F0A09292BE199CB2520C16381A5D1A9A5459FC73C22EDD459A39309025E989597D96150916F48B8E12513998CC30657C9E74D9D9950EE595E047A9D6EA0D28DD2472832BDF7F8AAC29F02EB551BB5F4B51052AA6AB197FA5E67D664063F147CDD4E49E41F46EB422D392B192857567A37D393C5BD4B20516D1D833660E2FEE63975F1D6F06DB80DAAC6D7A7FD95A5B797EAB22E6A78F8B7C803D76FA182F935D6D46B1C6361201A0233E59A88149D568887EEDE7F89A9FDF1F41C567BEB2C791A637FC0016E8E330FF9B1E2A977B8FD84915DC65742268FDB30F2BF7DC66B932B44BEC04C9BDD210CDBD1125F1E05E4D25B96C09D91F97ADC361B8F26C22FC3A32F26530E73AFADA8A&sign=5F240B6D54B181C4CC52191CBF9611EFB54F5B28 (Caused by NewConnectionError('<urllib3.connection.HTTPSConnection object at 0x7eff3d67c710>: Failed to establish a new connection: [Errno 101] Network is unreachable'))
### 执行结果
- **登录状态**: 登录失败
- **签到结果**: 

## 账户2
登录过程出错: HTTPSConnectionPool(host='open.e.189.cn', port=443): Max retries exceeded with url: /api/logbox/oauth2/autoLogin.do?appId=cloud&version=v1.1&clientType=20010&format=redirect&paras=55BFC46BC724F1EA3585CEE3817E71A690D5A3965CFAEFF1F969652B30C8E8D86AFBD848B560304D5FB78E2AB5DA6E3E8FCFEEB89F9CC2343AFA961EA4DB2608B5E8E34D551228080E5E5700F3395EA57936F5CEFAAD1A86AA65FA1A935C0E8FD00F065410E1C78CED23C2191C2678421D7B53520FC04ACB7748F7E07CBA66C7A1A3B5FC49E3A2EB0F4E748D28390C8712FFDDEDA3FCFDD7C255FAE79DC3EA8707142FD4317122B9A3FC16874A5926A11BD42721265CD3C391EAF73D7A87CDF02030A5D90AD4DB8954F696DE3449499A68CB533A06641CEAA7C80B1405DF3ED50DD0A3064C2876D383B06590A25F531FC81750C48ACE2184C389E7CE47C22680B391288F0DE5D0F0B67DBD7167BE2B01A87A3C29465B19CBDADDCF4CE795597DA908388F619B1270BA316C26EBC999D6DB7BCD17983276A7CC71D8233C0364D5A08271175BA4E9F21B68067F61132CC456C427E544280A352C47FBC6319067F008636882A7DB73F560E92341C1290A19710A3147667E0C105EE833AF3B1E20000AF71B6D6F4F8D1C243A1DC7B2E2D3EE8E6758CDE69DF2FF14C9CF5749CA3E132AA2ED734BE60EC0B2B85ED6BE640A6D06E2D879006D1DC8C13E93554C70A975569DAFF251DA9E6F10A07575A1A1CFC135FE05231E110EC93A0BFCB4EC6202DCCE83D924917BC7E8F47B331CCC0853FFC5D112D704D1F9E0C3F71C7FF861BCFFDB7D0C4C8531B352684B5BFDC64CEA428885629C89CBD04D&sign=8B11936F16446ED81E9E22CCB3F7BA48B15EF577 (Caused by NewConnectionError('<urllib3.connection.HTTPSConnection object at 0x7eff3d67ff10>: Failed to establish a new connection: [Errno 101] Network is unreachable'))
### 执行结果
- **登录状态**: 登录失败
- **签到结果**: 

## 账户3
登录过程出错: HTTPSConnectionPool(host='open.e.189.cn', port=443): Max retries exceeded with url: /api/logbox/oauth2/autoLogin.do?appId=cloud&version=v1.1&clientType=20010&format=redirect&paras=E9153A99CA95730C8F799ECEB5A1F266AAB663A1D18B03A3A52B528F6DFAE6047D1DD49498B22E358E3EAFDCD9C99FDBABA188B0E2903B17795AD378E33E073A6AE313F298E3F32940A0317B1E10BCFC9809B449B0B54590096705AD8487F1686AD1858EC97D5D2A7146B0FF0A86E92B0F4AC938C6822D82A8C3252A2307658BA1D7D15DCD408B84FF61F89E99D1E93966157BC355B744C0384B63F84ED94F97E1415C66F2F2B5AC3CCD947985D9B7D13373B0834994F060F6BC6B11DCFF6E2FE0D16EFEB374326D8BFEB6AD96337BE89D865FFF72C8B2585CC0E4D45D62BF23BA16A0708C7988672F6EEB74214E8D36758441856477E5168564EA3DB96C1CD3F69FD7EE908BCBDEF92B0D8346BA9FAB802812A7C5F8326AB61C0BBC456426D62E6A63D9A115A17BB8B61CF04BA42A8BBB920C39E39225B08DF95E2A5358D6DE843E771A680A8FE7DB36DE3259DE27A395D074B82AC94C00353AB6CFFF9DDEC16CEC78B43F6D186C86375FC9FB1109E91F27AAC36B250D471238112560D4B82D4AA4CAD7F3D560AF86314550BC3599EBFF4E63A56D3D8AD38AFAF2109925E08007EDBB4FFC7924E46D3497CDB71C3D87B352C3A9706FEFAD7404BE19430D6C2E957FFB08004371C79C82FE1B011DF3A560D150F1A4154AAA0946DE7FCC588D4869299FB51A7EED580AAD3207717A0AA518DD29617BCCAF67AA66DA15670F3599C66FCC0F2C712F7BBE8CB95FB14B027F0FC953A53C09ADBC&sign=2AFE594C23DEF9BEA028370D3EB2E009E2529C7B (Caused by NewConnectionError('<urllib3.connection.HTTPSConnection object at 0x7eff3d66f910>: Failed to establish a new connection: [Errno 101] Network is unreachable'))
### 执行结果
- **登录状态**: 登录失败
- **签到结果**: 

---
## 执行统计
- **结束时间**: 2025-08-10 11:38:26
- **运行时长**: 812.05 秒

✅ **所有账户处理完成！**
