# 天翼云盘签到记录

[![签到状态](https://github.com/mfvi/189pan/actions/workflows/main.yml/badge.svg)](https://github.com/mfvi/189pan/actions/workflows/main.yml) [![项目主页](https://img.shields.io/badge/GitHub-项目主页-blue?logo=github)](https://github.com/mfvi/189pan)

**最后更新:** 2025-07-24 11:19:07 CST

## 快速导航

- 🔄 [查看Action运行记录](https://github.com/mfvi/189pan/actions)
- 📋 [查看最新运行](https://github.com/mfvi/189pan/actions/runs/16486939615)
- 🏠 [返回项目主页](https://github.com/mfvi/189pan)
- ⚙️ [手动触发签到](https://github.com/mfvi/189pan/actions/workflows/main.yml)

## 签到详情

# 天翼云盘自动签到抽奖程序

## 执行概览
- **启动时间**: 2025-07-24 11:19:07
- **账户数量**: 3 个

## 账户1
登录过程出错: HTTPSConnectionPool(host='open.e.189.cn', port=443): Max retries exceeded with url: /api/logbox/oauth2/autoLogin.do?appId=cloud&version=v1.1&clientType=20010&format=redirect&paras=291E96706C5A6AC0D5906C605C481158EF1478F0C63F5F0AA7923AE3CF1A56DF196424091019F17F04820103EC2B37A9B34C44C91155246AADE0601EFF36EBAC41F65AAD8618D819087B939DF510A3EAB7AC23C7C2B3F85ADD2B5289F320B4264A89193F2793414B628D4C4C1523D0F78A9DBB64FACBB232659635AAE95438431C08D3BC727C8F07D7FDEE21DCED6F9985428F523F71948A9ABFCFDD7986E8799073BA6864228264F90825470F5C11624BFC2D023AFEB6F7A76079E3A31E4226A48D363505B9B48603B49D5A22F38F6F52230224034A17D14324F7FF75E230268D720C6ABD02B27B0E1B6CE6C6BE42E1EB3FFCDDF130FBA910D727C4799155A306A19BAEC40A19444A04D5D38728AA93385AA6E5E1EE63939C6FAEB9189C9469597C890DAAE8468DA459730A6BE33DD556323EEADDDC7F4B6B7A383DAF72B4AF1C1AC6ED372D21C19EB888855B4FF1496B4110A3286676C56BBA80E36EB04DB014F8687E6544B257D9562F39E8DFF3166A2ECC87032A40288230BCF9520ADB2B207DC1CB00F835D1FC2FAE9D4CEE3BF79A119754E65B2C5773BBE032CCA38AEE93B6E6C2883EE0F32E409AE1FFA67EEC19D745387EF3DABC5EB44969E01B36B0D689E12EDA2D56A14E1F2197616825BAA3F044E558C0AB4CCCD816D8C7D7135D465529A27F59B756AD2876B990835EBFF7BCAD1F3B886D9EE8BAC7E9774D7F5F04A6231914952670AB1532FF453C5704AA7939195C4DD9CA&sign=5233019244BA367779199664B13D20753BC1CC5A (Caused by NewConnectionError('<urllib3.connection.HTTPSConnection object at 0x7fbc53d90710>: Failed to establish a new connection: [Errno 101] Network is unreachable'))
### 执行结果
- **登录状态**: 登录失败
- **签到结果**: 

## 账户2
登录过程出错: HTTPSConnectionPool(host='open.e.189.cn', port=443): Max retries exceeded with url: /api/logbox/oauth2/autoLogin.do?appId=cloud&version=v1.1&clientType=20010&format=redirect&paras=D5820E7064F799ACF2C35BC74618694DD6D04951941DA0893A41DD405153B90E83D3C019C192A882540FDC246AA01709E5898A860685D0753CD0D2BE5D2B85132428DCB9B7E59F0A178C026E80E1D45B007C00BBD5229551983BCB893647030045DBE5E441589F64FB3430332E80C7D41A74485F2B083617C81DD717D5A112C51CB5492ED175B40E8E5CC8C2888E8A3B500EDC4BC5A63B73C21618AD1E0C05739A121314DC1619E9AB8A55699752F0DE81479F760CC36E7C74603F408FA5662ED462638E590E64890EF5FE64502F7D4AA553F43107CDCAF6603BC3D1FF578E89864C8EFCA5F8DE141ECC83210DDDB247DE8C4B06175E6E00AF217C648F92B0797BAD4BC8BD96E33BB8116BC4BEBA18351C1884F477CE14AD50402F4C81C233340A0C285FB3B3DEC6FBDD49E8BB2AB980ED385F950EFBF8FFF4ACEBC71E982010037C2622E06C53C2CC74DA6C1FCDD911CD782B4130BD03ABDD6C540F6683802AFD9DCB5C0A164C7626C99B1B5568C3B9BD8D38AF550D2ECF4BDAE01A4D7DB67E9BD07900D8C6E926F82760E808DAD948B02940D1F69B450AAC365435D370B73BF15030DE1ED761401BFB5F5F30E9368E5D23A558A15F6B818A74E198705C52BD2B03CBC86A5734A204F02F23D17BE8B3E6170139706F994A3FD08C7AC69BDADE1C5DAED5C5E482BC6CD85DF4AB0E59FD15C4B54A0BEC89DD84909D52F5743AD45A3CABB2A7A376290702E61EE97E06444A99E1DAFF16302C&sign=8A48E32D344EB553F44B7D6E2189860CCB8A08DB (Caused by NewConnectionError('<urllib3.connection.HTTPSConnection object at 0x7fbc53d93f10>: Failed to establish a new connection: [Errno 101] Network is unreachable'))
### 执行结果
- **登录状态**: 登录失败
- **签到结果**: 

## 账户3
登录过程出错: HTTPSConnectionPool(host='open.e.189.cn', port=443): Max retries exceeded with url: /api/logbox/oauth2/autoLogin.do?appId=cloud&version=v1.1&clientType=20010&format=redirect&paras=506FBBF69606303A1CBF64871145A53D6DBBE9FE629B63670CAB3C30ECACCD0BD7E69C978BA7F70DACF4E936C7DA20AD9C029FE1214424C8B0808EE9BB75DB93C65C32A9292CD8047ED3EFF00D31FE996CB7BD68F602DF83B191F46DEFAC768EEDAAEA6199C892E0A768CA4116B7F0A717CE5EBC9D7DDD90B283A9AD4F23E75D89AE276B63F0F0C1B472D287D8C451E559B6DBFDE337F320A2FA3DFD56C84B2D4E0512DED6A4D588688A24431D03330659D045E22C0303DD2C6F9E1FEBDB9D0942F8962F797A0938A798303929EF361B0204D14EC0E9214BB853098DF0AC5D4276B2D78C0A770D00753D274393DCF73CFF39320A3A6F6F42158E5EEDE35C727578D7CACE5812507B40505F9B14BE717E05882F83F729D91B381E3F3E102DF3FFBCB14E1E01DB1BF3DA7D3A2EEFF0C9B0C2BDF62E4F9C5EBBC2276804349B3A311E67CC39EC1555C6B68FED61B4AA61B193270B44930BECAF28536ED23C1B88A45EDD36BE17E17368E8A5B2B82AEB99C08EACB95766B85C9D2C3C4576BA4F5D2C57D2231367175AA14F2890292C8768AE8F97E1D38914528B0F46DE7EF709A959DAA18B612E8B8F0E524E4C47A67AEFDDE9D56EF4EF502D82E4838345CC21152E8257724F27E152F0ED405063E7D9AA304D775B003DB5AC679114774D9CE4382DE58036CB839690BE3100FBCF8100644A7AEA7C7A57D86A97E3B8DA63FA335E44412844647EB40B85B24630DAB0B1F1315A9E60B3FAD2E9CA&sign=CCE8A73814DCCB756B7EAC885399442B863DCAB8 (Caused by NewConnectionError('<urllib3.connection.HTTPSConnection object at 0x7fbc53d83ad0>: Failed to establish a new connection: [Errno 101] Network is unreachable'))
### 执行结果
- **登录状态**: 登录失败
- **签到结果**: 

---
## 执行统计
- **结束时间**: 2025-07-24 11:32:38
- **运行时长**: 811.51 秒

✅ **所有账户处理完成！**
