# 天翼云盘签到记录

[![签到状态](https://github.com/mfvi/189pan/actions/workflows/main.yml/badge.svg)](https://github.com/mfvi/189pan/actions/workflows/main.yml) [![项目主页](https://img.shields.io/badge/GitHub-项目主页-blue?logo=github)](https://github.com/mfvi/189pan)

**最后更新:** 2025-08-19 11:00:13 CST

## 快速导航

- 🔄 [查看Action运行记录](https://github.com/mfvi/189pan/actions)
- 📋 [查看最新运行](https://github.com/mfvi/189pan/actions/runs/17058326725)
- 🏠 [返回项目主页](https://github.com/mfvi/189pan)
- ⚙️ [手动触发签到](https://github.com/mfvi/189pan/actions/workflows/main.yml)

## 签到详情

# 天翼云盘自动签到抽奖程序

## 执行概览
- **启动时间**: 2025-08-19 11:00:13
- **账户数量**: 3 个

## 账户1
登录过程出错: HTTPSConnectionPool(host='open.e.189.cn', port=443): Max retries exceeded with url: /api/logbox/oauth2/autoLogin.do?appId=cloud&version=v1.1&clientType=20010&format=redirect&paras=0DD6DDC1F2E4D42E145E258D36527F6CDB3DA6ED79BA33130E1FAB4D44CD44CE66578EE1E45E7D22ECB234B5B5797B7F99295FB884E252D15C3A3F6A961072C371866B2D0C41798B786D957BB6B257818C7699CCB234C1651F49D34A6D0E67B0453D84A4A6EEA00C6AB7F01212F79D402F89989B7F545C673D2C2FBBAA4702A3D593C10364B787EF38F5FDC1A01BD4D99837268C388EE1EEA44950974D3B58B82A2E7535AB8515DA4FA47776C78B64D70C331FD92BCE83C170576788EE384280C5115C3F567F67C0678BA0C62206ECA939615DDA893B33BF1872E9121687851882C3C1468C05D06FB6BADF67ACF36FB5E05E76BEA13D7DA3517E30FAB43DE4B619CEE33A5E5BCC439F52D60208FAC390D9C8F2955B232C67CB9698C1D5F30A3B30BD8E797CFFB4768C9EC2EBB262E1334EF0C9EF436CB84F5121CB6884AA9CEF3A27B471A6F83F7F19782ED1CE07F3328C198C6D1F2524766E6FB49182281AA1195CE50144E7BAA1894EC125741AAA499E03EB43F75BB0B143D3ACD9A1579058C9A7FBEB58AF248858A9D44D5C7FDBF243DCB1142D12C152DDC13B14CDA2F6B7981EC63EEC426E2A2A25E394BCB97C1C72216BB297A417DD6E9F4A6BA9634A5B196E415811B00AD2BBB4892C665DE9C9C455C663D9320B425407120114E7106D5306E165B1EF0B916551F5BC1AE36D10795F4CD8AD0D777AFBA19B8F4570836EA069C17310527108939353EE65323785D58ABAC723F7D742&sign=7B124461499DC06F9FFFAA8788B88B9A0FAF13C9 (Caused by NewConnectionError('<urllib3.connection.HTTPSConnection object at 0x7f00c3248990>: Failed to establish a new connection: [Errno 101] Network is unreachable'))
### 执行结果
- **登录状态**: 登录失败
- **签到结果**: 

## 账户2
登录过程出错: HTTPSConnectionPool(host='open.e.189.cn', port=443): Max retries exceeded with url: /api/logbox/oauth2/autoLogin.do?appId=cloud&version=v1.1&clientType=20010&format=redirect&paras=C13099B7053283EC69D72B0BCCCB07DBBDF759282CC2BACD846468A7BD9C98DE9707BB428BAF308599D33DFDC9633EEFD5A963A2933393E96B2699D40208CACE9E0A343AFE13A737F4B842180D13E68C00FFB7B69A547EDC460D5ED5A2E24D9A21320F4971327D7AFBEF55DF66BD2CE18DC784CDB9733843707A0500A484AE53AEDA492C2AB1AB214AA2E5C755C57F8AAF7E640AA80660DBAC4571366154BAB39A857856D64000C551C02E56AF08E805B601BE60268CD3E398F478ABC37CFFA380A694088EF151736ACAAC2C5EA32AD50C24D7AB8BFDB63A32EFE4768BBB0E7F24474CA85CE0447FD465CE54CEA03163B8D17A4DCB2D249AF331F5428EB63B8DFD32AC4B78170F4228E7BFBC2D10DF6D7278D0DB5E2C0B96CE6C0A832A42D8B5ABCE0E77800AB1FA875A659D864B88D936F4FAF6EF8BF11D72D54861BE9B8CDF189AEBA366294276926F8175C9F4E3FC679ED7FDE9D17BF562F0705A8FDF1239C5E0230427C16293A50B511E03ECE3E0564F65AF003151160DA085EAED4BAA025AB9E422A9FE063FE4DCB3C56742E5C8EC555688C4AA4DCBAB9BAC6147B66B94F6A6DD398CB441A0D6C79C3B22AD6838F80751F1FF2BA8ACB7CDE258A030A06A80CA1D57DA5E5FD9DD3C91A267C7914910B7134D3311437457F7BF7F4E8C4BB6F8EA9F2D67AC649295DFB01DDCE0DA64120567D00FAFF167842C3837D400DC7F2AB90BC8F25A2650D1B70E27F6DB9FC97D06C763BCE31BEB&sign=60D6FEB2DCBDB44094A702A50720E68F08C36359 (Caused by NewConnectionError('<urllib3.connection.HTTPSConnection object at 0x7f00c32501d0>: Failed to establish a new connection: [Errno 101] Network is unreachable'))
### 执行结果
- **登录状态**: 登录失败
- **签到结果**: 

## 账户3
登录过程出错: HTTPSConnectionPool(host='open.e.189.cn', port=443): Max retries exceeded with url: /api/logbox/oauth2/autoLogin.do?appId=cloud&version=v1.1&clientType=20010&format=redirect&paras=D9E2981CC590F2CF105486E8CEB76949596FD227DDF1C33F1EF67FC05E5A01E6E5A3EBE0C016A1A84B2BF5C4A23803E64643EDA522072B9A9BCA4B21117A89895BA2F0AA8BEFD721E50C4FEB054C8DA70805C4DD3EF9FE9E6211D4601B37FD883A3FD776691DC05D5F8BE2AB150BD635B316D58EBDDF2FEDD225236D0A9A9AAC517B78E9EBE836757A3F82CB686ED982ECC3060436557DC7261BF534E6325702FDEEF36CEF5ED4D3632119969878BF7688EB05D94A61F07ACEF4FC9D553500ABC77F4AC6045844677761EFFC121D519B5FF6FB0C076A8BC6A36FBC0FEF0FDC5586952961078D01624049D43363D481014EB91458532F77BDAE7D58426318828D441FDA7A0BC95DB061B3A97F2106015F921DD63B8350E566F040F0C42D6C7514343E624BBC7D3E571E037B5C1B98022B7ABF80DD14BEE151CBFF4C876D081991DEA9F8EFFD2AEFF47B05AA5AB68447925897C4CFB15707456B6893FB8A97DFCACB96AF2E7964979395A9D74CBD926D4387FA42D33A8F47C5F14BD97010E1D18A548503CC4FAD7C1D8B8BF66BFF55A0CF8471D3E4769FFAEFD8EF7482C23319BCE6D713BF7C36CCBE38B508BC1169853C2EC67ACE6BA40075CF13D1ED86F5D4D206DF3274F0C8E5CFD27CBAF6953F07BC15AF6D1215E803AF3C67D5EEA5E3266F9CF56A570F4C91797B1BB7B00E3611257D436413A8249C0EF35A3EF12867AD04EEBB7E59FCA844DA9F9A73EDA78DD301314FC43390232343&sign=D7E685DCCABF43C74339099D73C4C2D63463B09C (Caused by NewConnectionError('<urllib3.connection.HTTPSConnection object at 0x7f00c323b550>: Failed to establish a new connection: [Errno 101] Network is unreachable'))
### 执行结果
- **登录状态**: 登录失败
- **签到结果**: 

---
## 执行统计
- **结束时间**: 2025-08-19 11:13:46
- **运行时长**: 812.83 秒

✅ **所有账户处理完成！**
