# 天翼云盘签到记录

[![签到状态](https://github.com/mfvi/189pan/actions/workflows/main.yml/badge.svg)](https://github.com/mfvi/189pan/actions/workflows/main.yml) [![项目主页](https://img.shields.io/badge/GitHub-项目主页-blue?logo=github)](https://github.com/mfvi/189pan)

**最后更新:** 2025-09-10 10:43:34 CST

## 快速导航

- 🔄 [查看Action运行记录](https://github.com/mfvi/189pan/actions)
- 📋 [查看最新运行](https://github.com/mfvi/189pan/actions/runs/17601529566)
- 🏠 [返回项目主页](https://github.com/mfvi/189pan)
- ⚙️ [手动触发签到](https://github.com/mfvi/189pan/actions/workflows/main.yml)

## 签到详情

# 天翼云盘自动签到抽奖程序

## 执行概览
- **启动时间**: 2025-09-10 10:43:34
- **账户数量**: 3 个

## 账户1
登录过程出错: HTTPSConnectionPool(host='open.e.189.cn', port=443): Max retries exceeded with url: /api/logbox/oauth2/autoLogin.do?appId=cloud&version=v1.1&clientType=20010&format=redirect&paras=18FF83460AA4C9F4DD62AD561AAFD42C3BD67C647113298C5221AD8F9907CC0A70DFE1C8042D2DC09EA0B105690093BF060D95E11C2BF2E1299BDD44635E52345E5B929DDBD90452CC1B849A5F31E8F00DFBFAD351BCA2ED00B8D6F0A2272AD20F48706FDC78478BF179B9C2536BE4D6A1348D687306FA135429C8D0281C302FE421A993C39C042C456EC50738956A64E3B29A9839A4E688C5A5351D52ABF4BE109AA765072B1244494B1563B57EECB2788C6DF39128F884A5E1766601F27C7F9C8D9D114D8D68A527EDDB6B92EFE91CE3AB79A3DE5A9D7F3DC5E5FBDFDA8E2C4444001F5714547DEE6E811DABAC8CC7C67CBB2A284D59E27F2C352AFE82071D7292E83CB53D909064D4363BF1DC79F5DCD99480D1EFE8F7E9EFE959789BB55B8321B06A96208E3C108CC52ED1BD22BB568C4DF622EEB80CC5C6A4FC761AC6497D9415FD7308E21867DC1DC2B026F7403DF8FC04442B7B8B31BC58FABD4B01C81DF669D93448EBDD57C2FF5F4998622634C65DF0D213592B0EE441F9D3E7E8DFB7639AC39AA03C696AF78D9EA57B5B67D49A3E2BC5D4CEF579C38E316D9CB420797BA3A33EE49B0C55B8C4DF548A7E161C6F9BBD06AAB34B8083EE8CBC59B66A25245DB2669CDDD389855C83F5ECD01C0ACBDEF19E0840E7F075372BE842CACFC4E8C3E0841946E4167624B2C5FCFAF15CA5534DD72270D65974749F91317468DFA7F79087676D49D1745D819B964C3A1D54B695F5793787&sign=68CCAB1B0B8BB1CCF8CF221E2A1BD93973F4BC06 (Caused by NewConnectionError('<urllib3.connection.HTTPSConnection object at 0x7f6070f88f90>: Failed to establish a new connection: [Errno 101] Network is unreachable'))
### 执行结果
- **登录状态**: 登录失败
- **签到结果**: 

## 账户2
登录过程出错: HTTPSConnectionPool(host='open.e.189.cn', port=443): Max retries exceeded with url: /api/logbox/oauth2/autoLogin.do?appId=cloud&version=v1.1&clientType=20010&format=redirect&paras=4341D814B022A4C2C6E93B006BBC7FF4DBF89B7710C68C8B192E4110B9D53A37756196C9946F928E09694BB74B96AD8B6CDF653035972AF75105CA33E45C2D74468DBE9FBCBFD9D0B8329DB0E49F9FDFFC96FA9812BAB863EF362FF6E82AA5D1982346806AEA2ADA6C9090490ACD593A48CA2DA3AE89635537CFA3CE7552E02808CD67A0296A44DEA69A13E89A4FA5B07C6D184FED314C708AE422030213A2A03452582B9EFBB6BA00E5175A60A83B6297DA375575D5D5A013AD56B27F2506EE7D608B3185B56560AC47ECABDF965404AA5C69856C52BAF08DE8725E4470349B283BF6F0342BBE44248EC7B98795AF2B40754A03C6430BACFA945405A8E5ED8104F69E06E029FE9419C226ABC01D12E406BA07F328A59A2D8D6D1C80EDE7DAE0B668CA4BF84EC95758FAF0709376C1FB2BE9905F93BC094EDAF7B5A3EF4092151FB9C73CB09F149CEED853AA146158A93BAB923DC54EA1E141395CF26BA2B3172A4B62B5D212833D470CC30FCE196042DA0F064ABC5BA38992598DA61E1D2C2FB9332FB57831377B4AB04F9DB5F9299CB3EA60BEDE27A931BD03B1A0EBBCA245AE2A899A0D6EA075D77DF51F4AC0D6BE192EB68FA1A97A61F228202E47C09BDE0C6861F6073EB7E5F1D8F90E711B50C4219E548CBAD4563312F88478C71891D10BF39015FEE8752A381E76530EFE555B004BC24DD1C5B9D203D8540A1134EBE591700C0C68BFAC8433CDEA79833C60A7319E7C7970C1225D&sign=61B964E26BC53A16EBACA34C71CD2DDFA8C06092 (Caused by NewConnectionError('<urllib3.connection.HTTPSConnection object at 0x7f6070f94750>: Failed to establish a new connection: [Errno 101] Network is unreachable'))
### 执行结果
- **登录状态**: 登录失败
- **签到结果**: 

## 账户3
登录过程出错: HTTPSConnectionPool(host='open.e.189.cn', port=443): Max retries exceeded with url: /api/logbox/oauth2/autoLogin.do?appId=cloud&version=v1.1&clientType=20010&format=redirect&paras=B0ADB08FF109DF0FA08F2352241E022FF4F57BD4C9606F4A8B291B851255AAC7B54DB8883749AAF6C3CC22E5F022BDE954234C5BC258EFAB930FEAE10998C25BCEE7894D9B5A8BDAC225BDF1FDAFB705CBF3A4B7744BB1F62DA01331D4B37FF15D759828D24C2A740B5A153E0538AF6E9C774DAF383ECB62376F3A5F4815EE5702F1BB8C324222597A5B94B84667027E651A5984C29C7D68F22236987E3042B1A368DD1F9DEADA29B136E03A28C5A34AEBDBD72DE7820AD320CEF96041AE5D2391D5F4D9E528E3F0AB77F85AB970F13FF7C73C098D7611306C0471207796F036C1513862B2E4BDC25B1C3B1563B9452F1FDFCB9164B743BB7B19153C004A57EDF31397A05D397DBD6AA65A6C1DC5B123E2A19A79DB34D303433E97534E20C6C6A227DE9CB22504D9E65AF8161F3C021164E0D2A550F4407DEE34672FAA2E2E05378F3979366DB9F2F554C6072F9B10B83C03B244F18D13FA047436B62E7F9D18BC4BC698DECF2D0F9A354CE407A5D933308191C8A0C0EAE461101C88AE43A3E724AD5C1DB3472FBBE36BC615306D022EC1BC88BAE54FB884B021C3E12C34B9BD54FC52C5BD1671C71D7082304E33F990B752070045DE7FA29B325C2E1A53276A755170CF8BA033BFEFF02816EEE313C9CC6176B409BB5036F9AFAE48BEBA7DC34648DCE3809EA5161F62F2C54E8F15CD26970026F62599670D8CFA8B79F2B70DB1A68099975959DD28EE0D591A2DC64D166CEC371B7780E2&sign=D0720AEFAAEA361EFCE2CC06AA7863A9B69FEED4 (Caused by NewConnectionError('<urllib3.connection.HTTPSConnection object at 0x7f6070f7e850>: Failed to establish a new connection: [Errno 101] Network is unreachable'))
### 执行结果
- **登录状态**: 登录失败
- **签到结果**: 

---
## 执行统计
- **结束时间**: 2025-09-10 10:57:07
- **运行时长**: 812.36 秒

✅ **所有账户处理完成！**
