# 天翼云盘签到记录

[![签到状态](https://github.com/mfvi/189pan/actions/workflows/main.yml/badge.svg)](https://github.com/mfvi/189pan/actions/workflows/main.yml) [![项目主页](https://img.shields.io/badge/GitHub-项目主页-blue?logo=github)](https://github.com/mfvi/189pan)

**最后更新:** 2025-09-29 21:47:19 CST

## 快速导航

- 🔄 [查看Action运行记录](https://github.com/mfvi/189pan/actions)
- 📋 [查看最新运行](https://github.com/mfvi/189pan/actions/runs/18099213133)
- 🏠 [返回项目主页](https://github.com/mfvi/189pan)
- ⚙️ [手动触发签到](https://github.com/mfvi/189pan/actions/workflows/main.yml)

## 签到详情

# 天翼云盘自动签到抽奖程序

## 执行概览
- **启动时间**: 2025-09-29 21:47:19
- **账户数量**: 3 个

## 账户1
登录过程出错: HTTPSConnectionPool(host='open.e.189.cn', port=443): Max retries exceeded with url: /api/logbox/oauth2/autoLogin.do?appId=cloud&version=v1.1&clientType=20010&format=redirect&paras=5F51B6E0039ACEE47A13FAD3714675758544FB6A6141D217280B9D0C0F52968C33DE8F1B7784F3CF07902067C83B040368216EE0C4617705C8CB192DA8E094651CFDBC0F7390FF878B2DBDBE3E0BBB41C75AC9EB71575E137988A208B0684139096EEE5502EBA9657497104292E72611E4806A2D755DB0DD934937F3C6A3DD04AF08092C4EBB64927A9D75D5490AE0C967FEB9B7FF6E95EE4012F8A7D35CF2545FB51B8BC02CA3EC70D803B6DACAF9C0E6A97D2967035E4170E70BE078DB83CDA243A1F3749CDA05554E7617E4BC3CE662373501939F389498CFE0A276171FD58FEF39B523A9E322B6F7CA5D8656269D63FE5D16804563AE819F5A478A396CA8A2AAAB00D0F62B06E2B67C249AD58BEDB46B5AD5F2E2161CC2ADC642075A363D4959BD3BC7885895975DF59BFB4780C4FD283D0EF9CC33CCC329AF81A673F8060ADC8F6EA953D7AE7CE3BF5B5CBB71E4406216A5C7CC33FFA4F3BA3A45E1498B683E4B79E282ABAE7DEB45B989E4AEC2A8E2423DDC3345464CB32A3994A41CF699063A7BBE28ABDCECCC32D42DBD64CFA66C4690C3838456A2A72E1943126BC567F060C805D2CC0125476B3F93CB868F31A828827776C7A6DC9F1151D7FB3E8BD9B4643836BE64E660D6D6B4BF6EED7A53611CE458C7175F3B87EE7448DB73A0B5EF37150DDA86B646B68A91CA08909B7B2FE6343106F102B21043AD3C0C0E7DF328705F17B9D445DB9B4C088371ECDC774F00B43FA777B1&sign=6FD6F081F891010DA7437E41A7463ED026F54544 (Caused by NewConnectionError('<urllib3.connection.HTTPSConnection object at 0x7f0094690b10>: Failed to establish a new connection: [Errno 101] Network is unreachable'))
### 执行结果
- **登录状态**: 登录失败
- **签到结果**: 

## 账户2
登录过程出错: HTTPSConnectionPool(host='open.e.189.cn', port=443): Max retries exceeded with url: /api/logbox/oauth2/autoLogin.do?appId=cloud&version=v1.1&clientType=20010&format=redirect&paras=C7D9DB18CC9954C05938FFA69B695331B21868E44DEF8B894AAC25B91A12CFE5650256829D643600DAAD22AE48ED82369A72BD62F51C7327D842F9722F153ADEA0168E17A46C3A0C1C2A2BBE086AD3B1EA2C9467E884DC173E67C4A8C8F9D5A9AD2C9F9F472A5A1CFCFAAC9522158745E065C85FE4393F4812D935FBB0C898D8FC5C4D3B0A99DEAD2F509AEB2081493113D08902CB4E3F8AC4C8836B719CC5EA5C0023478EE67B41551E8793BD879988E40A632EFDBA88C7C893C1847699A3D550CA0054DC010981DF923D694AE549C2DCD5B5F9A3CD5D36CC284AA225E780C5C58C551513C028030125E40CBEF714C1C6DFCDF24F55C6CD620B858471ADA20518A39C33FF2C8FA625BE358FC5C708946C727645572E5DF6CEAA2ED40A4EDFB4856E42A6C68E6EEADE860FE14AFD138C316A75A5D2A2103EEEE9044833D86774449D338F48158F603BB41DD5EDF97C15CC8281645E2B43F1FAB097A22CDA8A16580AD9D7DC3179A2E652EC5FFE18DDCE76480CC3550D2E964198AABAB4C9D84C2C5B0BCC89506C10A0D17588BA0A11AB77EAFB5A5F9372B3525C168B48AF79200E772EBFDF0AF08ED5053BF6BF472C8ABD6FC0211CF8EFBACD1C17967BEC1BC2D9618AED3D172CEEFF53524778D6A4C5BD249710369458CDC8F228E8DE2F8275B6C2779DB7750D2EFAE700967BB292838B492CB23DD44EE96192D8241AC6D317F3910B9D49B318FB9011D88236BB098C95AA8D020183AB7E&sign=4B2F984C36B130EF8B6D34FDE37287B218221928 (Caused by NewConnectionError('<urllib3.connection.HTTPSConnection object at 0x7f0094698350>: Failed to establish a new connection: [Errno 101] Network is unreachable'))
### 执行结果
- **登录状态**: 登录失败
- **签到结果**: 

## 账户3
登录过程出错: HTTPSConnectionPool(host='open.e.189.cn', port=443): Max retries exceeded with url: /api/logbox/oauth2/autoLogin.do?appId=cloud&version=v1.1&clientType=20010&format=redirect&paras=DFFBA70203AD4A414E2DD2D3819445DD176AFB97965E949AFFB8D92BA100AE480B26DEA8E0A456D2F2FE22064543B89D83848F85BED833FB3DDF8E4D62CC57A66F92F686F41CB4F81A5E472240DE53AA8A2BFD4B15A864545ADD5908FCC80E6EBE61A70811437A90E347F36BFA1C0584475DDB3EFA8C848895130C6B7D9FD4AB6EFF59E8A780E42352EE4110D8B396864CBA4D23EB0A7F0F449B7E04687B3E85EBAEFF8FD95CE9FD82A2A2AAB4E48FEE4EA8C3B960F2EF5F13B4DA584506D24A10DDD914F55DAF63DCCD34946D10DF65147B680AAD20FE8B00E3D11C826A04F9BCFB58CB14B997AF06CD462BB8A365C99501469EFAD266CE8E69FEE96A134A5C895222C7C6FB4E6AE935F3E165E9444069AAA8B67E8E8DEF3AD2430B84987A75E4EA794177A5C0A0F36D6B6900AA143DCCB2AD66C6BA0FB27B7A18D3E2D1DC7CF0DB09A5EF2D6A0085A1C8443B39F3ACAA9A7204465ED4D20888AF4C6D1562D4F6089F4E64EDE7F6D623027829BB859692B55D3EEA879E9E663892CA6C2842DA687FFA5830BA5B098934863D6BEABC1058035A529FC6AD74DF212A15E33A00231B2E603ED15B438FEA914AA385632B904053865F41728730D27B4F681DFDCAEF7A3CE01F34D22E0C2622B974C2BC6F637BFF127646BC9B9DAC147D8A2532960E89894C133BC69C51BE3EFE2A8ADB860402185C3564EB6DFCD85437F58B8467A83D6FC8FFFFB90D2AE1D7F985152B04C81F520B0A52301756&sign=AA5FF7C2C00CDE382F8D123DC21DFDADB3DA3F37 (Caused by NewConnectionError('<urllib3.connection.HTTPSConnection object at 0x7f0094683010>: Failed to establish a new connection: [Errno 101] Network is unreachable'))
### 执行结果
- **登录状态**: 登录失败
- **签到结果**: 

---
## 执行统计
- **结束时间**: 2025-09-29 22:00:51
- **运行时长**: 812.70 秒

✅ **所有账户处理完成！**
