# 天翼云盘签到记录

[![签到状态](https://github.com/mfvi/189pan/actions/workflows/main.yml/badge.svg)](https://github.com/mfvi/189pan/actions/workflows/main.yml) [![项目主页](https://img.shields.io/badge/GitHub-项目主页-blue?logo=github)](https://github.com/mfvi/189pan)

**最后更新:** 2025-09-14 21:38:33 CST

## 快速导航

- 🔄 [查看Action运行记录](https://github.com/mfvi/189pan/actions)
- 📋 [查看最新运行](https://github.com/mfvi/189pan/actions/runs/17711984382)
- 🏠 [返回项目主页](https://github.com/mfvi/189pan)
- ⚙️ [手动触发签到](https://github.com/mfvi/189pan/actions/workflows/main.yml)

## 签到详情

# 天翼云盘自动签到抽奖程序

## 执行概览
- **启动时间**: 2025-09-14 21:38:33
- **账户数量**: 3 个

## 账户1
登录过程出错: HTTPSConnectionPool(host='open.e.189.cn', port=443): Max retries exceeded with url: /api/logbox/oauth2/autoLogin.do?appId=cloud&version=v1.1&clientType=20010&format=redirect&paras=95DBBBD1480086A105540E5E328EB1FDB71998ECE1E54EF0182EF14ED6096D42D61132BD83CA8A73317AECDEA454D76C318DDE524B089B21D54FB8AD05B2A8C708A43048F211B2D18DBC4BA859D8390333AA737F21341EC37175CE9BDA42C82B6C7C0DC21BB26DA0DBBE78CCE9E20C00CCE9E84BD1099B38BFD2380D5B26B96480853C6178944F9A9E798FFEDBD618C327A5CFA87E34798BEDC5CFD79716D8BAEB5D562798B25639490CA605E20042CD5332C50036745A45C32CA3C94955B9F04EF09881E0B0DE7DBB74F52CD2D0447001C60F0AFBD458220C6AAC5861A15960FCC866B098D8F795FAB61B1776B1696C7BE15073D7C3ACD77D124E00BFA545EA9BFCACB3D24E402A9F673018F59D600C1AB5CC7246CCCB8FCECEACC2F9DEF1C80DFD8FC8E82A0ABDC29447C5B7437D06AC7EA6C34DFCEF5C27E91AF331D1D1460CE0D8B99A3EE83B5C686D242F1D679456ED0409A906B070E76B0DE6B3B2F48826689D92260EEA8EB4526EE811F1A8D4501744B556BB1C72ED1E614E4EB7557B947480F14416F2BA67932E6BCDBE7234E4D4294EA97860A3CB69DEBC91B04F274D2878B7F94722F34A5530FCF6F8B7DD633AC0ABEC19083722260E0CC3BA86DCBEA3B6B8AD67D5A9AB132C214CDBCC7E547741E34403606AF6F88431DB2AFB18DEE9FDE4C73B82981C70DA9D723776FD2B7AACFB7877ED0A3B8FCDC92610CB97A4E87491E513F5E703DE5F7769F3EE774A729BDC40B54E79&sign=BF6E5F5F131FE8DF3F042BBEFEA61AB1F0D74534 (Caused by NewConnectionError('<urllib3.connection.HTTPSConnection object at 0x7f955dc58a50>: Failed to establish a new connection: [Errno 101] Network is unreachable'))
### 执行结果
- **登录状态**: 登录失败
- **签到结果**: 

## 账户2
登录过程出错: HTTPSConnectionPool(host='open.e.189.cn', port=443): Max retries exceeded with url: /api/logbox/oauth2/autoLogin.do?appId=cloud&version=v1.1&clientType=20010&format=redirect&paras=7924BFBFE28DD0C78929DB52D7A67833784E52576502204BAAE9DE68C8AA0AFFE3DD495316D749523BEBE747B3AA1F9E4A32BC377353EF2D26F95C57FE584E71FEB4BFBCFA9D432A861089D83A31E071A1C8C7153C3D3C1CABD3D735FF800582401E1C97A953668E0189622C50E5666D9B0DE39C568880659C2CD1088E32FC9BD59AF2D1B410C74318A07CD25895ED9DE37079335A1137D3C09DD8410720D6C2B3168D1165D2744FA1E344957A098C9B3781B36A01B2F93BD4FFFCC8A0E8C021F72AF81BDBF5738121B0CFD7749E2D21263F5D1376E6E5B96AC40E9185FFF69494A69D8C13659EACC4838779681B850CE2D800BF34BF29E514D925696807AA74E4793CE552529A3019575C14F5DCCB3BF86BA589CD7D7B1548A36E56F5C4E002C2B0C08805215AF0E0C029B49748F0C7AAC785F92840B42236A10681B9FB4D4AE2BC6106998AF5EB86823CD95E3086837C7C3DA42D8EEEBB2ADF408300D848064DC88086BBF0D9773944FF970B0CC71FDBEED387115E907F17184D9C0BC55FCB524F124A9A2CEB1E623B9809E3C4C1E6A203260CD35D606E69C8ED45C1A842E14C28FC944C5A262BB8913F0870D716753A5E2148DF76CC65FE2989EE21EFCD744553011F370127F403711CBA33BCABA8253F238EF8E8D5E253AF5B91575D292E705E07176A5DFDB87A1C185AEA6FA2CB4B19C0C58DE91C6621B539CD210B312A79CB553E990D7AC3DA4204A239DBB8D0A7C448B9DF32051B&sign=4E0E9B90CDFC50BEC1B375B4496EFA3B41ED25E1 (Caused by NewConnectionError('<urllib3.connection.HTTPSConnection object at 0x7f955dc60290>: Failed to establish a new connection: [Errno 101] Network is unreachable'))
### 执行结果
- **登录状态**: 登录失败
- **签到结果**: 

## 账户3
登录过程出错: HTTPSConnectionPool(host='open.e.189.cn', port=443): Max retries exceeded with url: /api/logbox/oauth2/autoLogin.do?appId=cloud&version=v1.1&clientType=20010&format=redirect&paras=F1313C7495E7CAC14A3449447F5EA497FCBE676382EB1162F377513EF932CC9716910AEA0795F7A85DAF094A758161A4B1F416F8FA9CC6EC3377157D050A0C03D2A060EAD12B21ED81D57454F8B25024245F53CFAEE8490A7947776633A736320595B7A66AD0E9CA9766EE9BAEE3F425E47178BF153C3C43845D2B9210D1C8A7AB219DEBBB5C94996117F1114DD18081125E5D01A96A022E10577FDFFC76029737BFB324BA068531C0BEBF9F53CB50DD12EAA3AE9A6417FA230FE3093B69E9D57A3873BB502262C6AC75EAEF138BD94827F21544110FD010A744081FD7697743D5777CE9EB75A6ECD98A18FBD7DCFFAB775A562AEF51E4369047793D566CD48EDFF03E84B12CF77DA09240C3FCD1C28FE37E7436630F937ACF6A2E3A5858408F8A2B506949A370CA271D70DBD550EF0C28FACA72797B9BD565DBAF15881F1A77F3475D59FEB1EFAC91147326169D0BA50DBCB3C50B3D01E57ECAE685078464601E8DF531CF1F82B81408A46E92CF68910C371F6BB2D28475D16631FD14C8396078C95EEADA22907A81666B591D772F7F8F3FE597FF3E233211ABF38D401C69E65687388096C7194C61EC82D00065B2679F7D5C6D866A597681BFBF2B48E5BD54E59E03F63D960F243932B4323096DB221970AA89EEE6FF7D63118E2FD2B121FD813D1C29A21468820FAC217304080145F849102169EE0A6B5665C539EA11FBBB98DE987B528D8DC960CEAF5D4523A1DEAFAA97060EB0C692&sign=356321C9FE405CDDEC78972D470D96DF1AAC7ED4 (Caused by NewConnectionError('<urllib3.connection.HTTPSConnection object at 0x7f955dc4af90>: Failed to establish a new connection: [Errno 101] Network is unreachable'))
### 执行结果
- **登录状态**: 登录失败
- **签到结果**: 

---
## 执行统计
- **结束时间**: 2025-09-14 21:52:05
- **运行时长**: 812.22 秒

✅ **所有账户处理完成！**
