# 天翼云盘签到记录

[![签到状态](https://github.com/mfvi/189pan/actions/workflows/main.yml/badge.svg)](https://github.com/mfvi/189pan/actions/workflows/main.yml) [![项目主页](https://img.shields.io/badge/GitHub-项目主页-blue?logo=github)](https://github.com/mfvi/189pan)

**最后更新:** 2025-08-22 21:45:43 CST

## 快速导航

- 🔄 [查看Action运行记录](https://github.com/mfvi/189pan/actions)
- 📋 [查看最新运行](https://github.com/mfvi/189pan/actions/runs/17157003149)
- 🏠 [返回项目主页](https://github.com/mfvi/189pan)
- ⚙️ [手动触发签到](https://github.com/mfvi/189pan/actions/workflows/main.yml)

## 签到详情

# 天翼云盘自动签到抽奖程序

## 执行概览
- **启动时间**: 2025-08-22 21:45:43
- **账户数量**: 3 个

## 账户1
登录过程出错: HTTPSConnectionPool(host='open.e.189.cn', port=443): Max retries exceeded with url: /api/logbox/oauth2/autoLogin.do?appId=cloud&version=v1.1&clientType=20010&format=redirect&paras=4191BAD0B0229C5CDC4C8E0B2408B0B4C10EDA57C54E366C7F8FB0CE7A1DF6996917D7A4EEC8E9057820205F015D321DF4BAB3CCFF486093DC48996B980344BBAE87030ACCD9A45D47775BFC4EF28B9547BF3C1E9B5CEE74DB93D16B55CC6069BDEDC7B782FDC2A61F6B0DAC9E6E5BC892371905F2A6BEEB78CB2563B3730BE75C60052BBCAC83B1128CD7C49FDDE8E834EFB2B6AD85F7C724C5FCC7D10096175F0A25EC5EC93560A960C2006D4AD4701BD2969A1E036300A18C05E57D85286B2821FE8BA6B7BFEAF7EB363AED783FB5874B7944E236D35B101784F5B72728A7F02446354D91CBE92EA2734FCC8DC345996222981449D56851163FC40F34F9FBE1E3479CCD18B4228573811A865B84F0FD84A9CF34E2F4B4521A144D33D8FD4BE8FB9875939CAD4FD0F2E123AE8172476BC42D6DA862F3131E905E30A6ADD6A94E3EE41D343DBE97A555773C3F909784B551E0BE5B609C8F8C984B0F5449C487B567796A21FE9AC98A042FC2F9E681F9F9A9055C0598BB256D48D650F30FD7B9343AA664A36739BF107C955E780121C81485FEC2139F3159585A4D086756DB25EEE076B26BB9D9C1B0EF81C63BB2C26D942B80F6BB31C2160022BA59E00FC148D05A8DE3124AA6B67FC98F5C7ECE2090D245B1B3AD7284C5595FBF759B11A15B5F49BCAE3B9849BED41C77AAEFE787750A18E45862F6760D5D16B827CE6B74895601593C966972AF17831F92FA40CE8E8AE5A870AF0C5288&sign=A78EA6377D0DB71BE6F544044CBC009CB7475643 (Caused by NewConnectionError('<urllib3.connection.HTTPSConnection object at 0x7f4c58740a90>: Failed to establish a new connection: [Errno 101] Network is unreachable'))
### 执行结果
- **登录状态**: 登录失败
- **签到结果**: 

## 账户2
登录过程出错: HTTPSConnectionPool(host='open.e.189.cn', port=443): Max retries exceeded with url: /api/logbox/oauth2/autoLogin.do?appId=cloud&version=v1.1&clientType=20010&format=redirect&paras=1A31F150F11C2BFB0D2CDCB6CDAB7C1B49CC3920852DA53BD9FE14FD88D2AFF1FB6E5DE43EDC72D9AE7E28E59F22F9CBA51C15911505F8686C30233DC1D6801A3039A2B1FCF9AA5C2C56F377D66A1CBD79D3485AD69230F9C104A305433DA65DDB0ED80D0E33F9B2E00A78468E6D592AF1331C6E5374194C4A5754A2F55042A0AFAC3DA5DA7FEE92E8E684E6886EE4D679E25C32F1ED7C32EF940A8AC7285B15B888DE4B739F54ED8F3BA1730BB83F3DAC828F1F933F05D2CD8538B5E601A8912A618959DB740635BCAD1ED2567BB14C3D84288D9E21125AACCA1246C59AF6736FF01BA293F7D416D1B5FDAF9D6B476D63715C6A2F2E31090996396E002E921B45EEC26A5B0819D4521C00724BB474F172E3282056F507B9AA72AFA7B3D0AB0D97C01C718DCBB4B051BA5A11752A4072E64EB93448736AD1E4CFB042D87C45AD9A21E0BB9CB6B8CF8542B6FB73687BC00163D4685AA1A05E8638FAFBC595CB31018AD85D6BBAA2C18E9C463C399508CC8DF460A626F79FB81B44DF4A8217F28C121616E95A46CE6AE233816C69625D2402AB81A5F729A7A1616C03D23122BC246DCC9946CF080CBD6C82DDAA8EFF668E946B0C79574B22B714CA25604E589A82A2E3E6C92D3F452FF4000571D43B874D5D257AE795FB6D2D9E93F53A771F718A12C5E2A005E9B83B3325BF24A88824789C72784093F39BFA988170370D62A54CE9359BC20C104D0CAF1F7A48BCEF660FE1875B7059B3A982&sign=18BF0B0D3FD0D0FCE635CDABFFB4C3F564D2BF72 (Caused by NewConnectionError('<urllib3.connection.HTTPSConnection object at 0x7f4c58748290>: Failed to establish a new connection: [Errno 101] Network is unreachable'))
### 执行结果
- **登录状态**: 登录失败
- **签到结果**: 

## 账户3
登录过程出错: HTTPSConnectionPool(host='open.e.189.cn', port=443): Max retries exceeded with url: /api/logbox/oauth2/autoLogin.do?appId=cloud&version=v1.1&clientType=20010&format=redirect&paras=CD4B640F0AA816318C648159D112DEAF320823E5CC2A64D3BCBFDDC798235A8A38925410DA6E3FC84F4641C003CCC7851B8A505B5C4C8280D0E3C66777673BBA4FB00B9681746ED883C088AE4A358FA23E3E5AE89C4AECE56BBB401340300A8F238B1657FCDF8055627F73E132558FB9149AF1B812FB7206FED7216E2FBD7ED318911BD9597FCB2312FFC75036D6DAEBD8706DF271867A6D21B92A69554A863294B3542D0B3D0E8F701B2A4E2B23438360C3A90CD87D41814FD090AC3F2E82E70128B9B902A4918B76107D18D1D898115957183B129606CE28A67893E281AEE6394DA80B2149EC583C902B355D93F709BEDED213FE76A735A28600CB18AC86EFDDA990414002E3A866BA07FFC5D93528FD6405AD74722B2C29FDD8E888B9D9B71999E05E9FC1D68EC043F71EB8E4240EC4D7A8C8CEFA765920750A52EB6565E51193934E762AE27AF168A56F88798688D82B095B1F714EEA70AC3799E9A41B6D97EFFF183D07415DD0AD9079BCDC08BDA8B1A67BA2781DFE24A6F797B8D1FD2514CD9358B049FE65107ABB7B1B5872908AC5C1757FC886345EE41F31E601A05B3881F484689648A11DD51C8D519EC1FB11DDC9D965B83495C0FF7CF40A5AE9ABCDDED3EC78B7909A9F5EFC86552D2C4D850336AC71D5214B949F14AD87A36CEA7A7C7DCCD9233D58FA18106D6B5B28080D99590FF4A69614D4F96A86DE1EC9FE0923196CE9F6CF5B872B2CDE58982B3A371137B0060DFDB1&sign=078E00413F528C88896078C990766D12EC8A9E5D (Caused by NewConnectionError('<urllib3.connection.HTTPSConnection object at 0x7f4c58733850>: Failed to establish a new connection: [Errno 101] Network is unreachable'))
### 执行结果
- **登录状态**: 登录失败
- **签到结果**: 

---
## 执行统计
- **结束时间**: 2025-08-22 21:59:27
- **运行时长**: 823.90 秒

✅ **所有账户处理完成！**
