# 天翼云盘签到记录

[![签到状态](https://github.com/mfvi/189pan/actions/workflows/main.yml/badge.svg)](https://github.com/mfvi/189pan/actions/workflows/main.yml) [![项目主页](https://img.shields.io/badge/GitHub-项目主页-blue?logo=github)](https://github.com/mfvi/189pan)

**最后更新:** 2025-09-21 10:54:45 CST

## 快速导航

- 🔄 [查看Action运行记录](https://github.com/mfvi/189pan/actions)
- 📋 [查看最新运行](https://github.com/mfvi/189pan/actions/runs/17888062619)
- 🏠 [返回项目主页](https://github.com/mfvi/189pan)
- ⚙️ [手动触发签到](https://github.com/mfvi/189pan/actions/workflows/main.yml)

## 签到详情

# 天翼云盘自动签到抽奖程序

## 执行概览
- **启动时间**: 2025-09-21 10:54:45
- **账户数量**: 3 个

## 账户1
登录过程出错: HTTPSConnectionPool(host='open.e.189.cn', port=443): Max retries exceeded with url: /api/logbox/oauth2/autoLogin.do?appId=cloud&version=v1.1&clientType=20010&format=redirect&paras=2004531EE10C4823B5C7461075DE807FF48ACD535D9B33C132E0054ACAD36EDFEEF32F41BA38EBE6C09740E034932D95D8B56B0ED32A5BE4D0D1B269A8AE44A73C44433BE8D4C862BCE1F207162D913F4B2E6B3AD8569068ED0FCC4656C0B1B34EBBA6B6347B66C7E212DCE16D502D2E8F76B316A43C2A93D5E4E788A748B499DFDCEE3CAB6ECBBEC68F0A710AADC8DFCC8E8AB90ADD47FDE8D9B3D37516E0AB25AB6141C9AF3F4B0F3243ECD223F3351D746859568009F3BFE3124F7A40287019B7267BD19C47BC9BDFCB30C5C54040E98EEC48F3D3177CD94AA9443CC1B87F7102F629A30D35FDC17E2EF3D6E125EDB2E477042D4AC7C23346FE4EB03BE7553E738F2798D94882899D319239C2610999BD0B2E6A1449D59D7B7DD8F474C2BD2E207D8F9FAF78ECC794F2671FC4ACA5D583AFD4482AEF934C1C88570E56C5A7281848136AC40B88DE7B637AA247663E5484A52C1EA32C6B0669349E88A4DA7523C079AF59D96FDE26436BBF20CD70770876E2B8804D9A8744F135DE35D195C396D29E28B6C1910D07A877C6C1828432D19609974DE040C35D8EC4FE1C92D35B926AFD66743CA6FA964151012C92FF2E9FBCE06BC0959EA45485E41F3BF5072D440A2FC4664D0EEAE20289465B1AC5745586A0EB213554742EE459F457B3E277FDF691F5BDC887FDA85DFA2AC0318DDDBECEA3E6808ECA1896B9E51D6084A53F47375329DA9FD58F0E1DD304DC39992935183EA92D2BA874&sign=69BDF013161E8DED2DF54294C24E2CB680A60A19 (Caused by NewConnectionError('<urllib3.connection.HTTPSConnection object at 0x7fac67b2ca10>: Failed to establish a new connection: [Errno 101] Network is unreachable'))
### 执行结果
- **登录状态**: 登录失败
- **签到结果**: 

## 账户2
登录过程出错: HTTPSConnectionPool(host='open.e.189.cn', port=443): Max retries exceeded with url: /api/logbox/oauth2/autoLogin.do?appId=cloud&version=v1.1&clientType=20010&format=redirect&paras=4213B017FEF030D68289B34F79DDFDC0EABE2FB4B54DA063D75336893D1FA1CA0B662072D273F550B6AC347C718CF9AB7ACEB999B23D4F390600DB442D12D08B5BB2DFA8970F89B6F87637736015539F275FD8D45482C2B00D0DBAC1E0DAA6988A0D830DE769BA03A10785D386454C0BF8F7FEFD73FB967DB1A851654A6EF6C50F4FFBE0C792D0B8100875AD2C8F1821E4490C4BDC3484B04748222EBE7D4DCCF32E76C5BBCB49F2236608D629CF73F6FDB1D0DA2F78D510ADB4E378F8D9CF6DF00210FC039324EF2133F8C43B29EB09F7E130571905B2CF3B6E8CE593C82AD2FE3018BD991E323AD487472F3DAABE5E9C19839893C4154FEBC35315709598DC22C9B19FB12FF85ADDD50C3F57B7AB1C2A8C174BDB768E721BA37F7BDCED9F9F97252F306C511E757E88177E13C44F3F339BD55F89B3420BBD12DD1C45B7D664E5F266C2C28B8DB7BD755187EDC2A583BE25BF1DD70785158B0B9FA4B468FB4D04E24E819C47326E795967748809C74478A35E94FC161FFFE567646C1F175A42BA2BF0B3DF86E540866D5887B5F8AFFA0119BA494DF57FD51DCE9721ECF378E0BC5516805D9BD739AD993D2836FF171CE129AD391BFB8D2B46B3319F5E5622DD447EF845184E6F4EDC7ABBCBCF0F54648462BB00F361A1FF06F2EBA7F71978710EBB9340F352DFE71BF08C077453027970E7AD7F7402016381D1FA5C7B5D12EA7CF00823B689BC0EE8AF243DF7B43306EDB51194A7B8581D&sign=E457874886234CAAD24021C7610731E51B6A8197 (Caused by NewConnectionError('<urllib3.connection.HTTPSConnection object at 0x7fac67b34210>: Failed to establish a new connection: [Errno 101] Network is unreachable'))
### 执行结果
- **登录状态**: 登录失败
- **签到结果**: 

## 账户3
登录过程出错: HTTPSConnectionPool(host='open.e.189.cn', port=443): Max retries exceeded with url: /api/logbox/oauth2/autoLogin.do?appId=cloud&version=v1.1&clientType=20010&format=redirect&paras=A545D07A00BC1DAA59D5F9E8274C4EB0C88266AABF4574C602CFF36FE5A9806908C896535AED07088C2F5F8E867D9A5DA62EB13B71270B68871062B40B8C652B6EE78B7C80901CC409C57E27D7C866ACF8DDC6EBD1832261F839250997513FC2CEDDB507863CCBC19C6B5394D4CA502643D0D259BDF60CF70770F4DC6E5E81C5CB20BAC3D39D8C5C3D0B009D1A726478B6B3FE0604315D1B532E40E833062DA766B0B29E3E9423C3D38AD2C5A2819A4CE7235A1EE875F007FC7B61934CABE1C7BB9DD573F5369FEB3DDADB2E7478B21D06E0C13CBCF480386527D5D3A198FAB5041C7F613493AEE4978518ECCD42E6D16767F186F32D9F04750DEF1DE6A3CF81EF76AFB1C1ED21F2BFEC0AB3877667EDCB1DFD9B518CE0B03F2F552CC9CBCC20BCE9C0DD3839C7B4489C85A5B362AAE8088AEACAC107CA6E738C959D5A3E0A85F7788CD43CD13CE295DE79CD783461F04B2BE85C8C0CF8892C97E814E7217252B120E71E3367F2A9559C40B3AEEF9649B418857F53A28021488232387BE5B29EA4793F926B55D60A446F8258FFF88D4B57B0575067E067EEA2EE46DA8454D409E34D8E75095CAE934CED7D0622D4EA777E59FA862B28E55B731F88F50AAFD65FFE9FB976343F633A56A00A1146E611A38397ABEAAE3D9E6CE46D1AB958F271C930B76CA0381FF7C856925B74CF3E9EB4939ED47511D38AA5F94B6B59831DB684D11562184D3852916B74283E54148293B7F2A865C35CD12D&sign=319D32E421711D4C2906B684A661126CCF3C7B15 (Caused by NewConnectionError('<urllib3.connection.HTTPSConnection object at 0x7fac67b1f6d0>: Failed to establish a new connection: [Errno 101] Network is unreachable'))
### 执行结果
- **登录状态**: 登录失败
- **签到结果**: 

---
## 执行统计
- **结束时间**: 2025-09-21 11:08:19
- **运行时长**: 814.16 秒

✅ **所有账户处理完成！**
