# 天翼云盘签到记录

[![签到状态](https://github.com/mfvi/189pan/actions/workflows/main.yml/badge.svg)](https://github.com/mfvi/189pan/actions/workflows/main.yml) [![项目主页](https://img.shields.io/badge/GitHub-项目主页-blue?logo=github)](https://github.com/mfvi/189pan)

**最后更新:** 2025-10-19 21:40:17 CST

## 快速导航

- 🔄 [查看Action运行记录](https://github.com/mfvi/189pan/actions)
- 📋 [查看最新运行](https://github.com/mfvi/189pan/actions/runs/18631253643)
- 🏠 [返回项目主页](https://github.com/mfvi/189pan)
- ⚙️ [手动触发签到](https://github.com/mfvi/189pan/actions/workflows/main.yml)

## 签到详情

# 天翼云盘自动签到抽奖程序

## 执行概览
- **启动时间**: 2025-10-19 21:40:17
- **账户数量**: 3 个

## 账户1
登录过程出错: HTTPSConnectionPool(host='open.e.189.cn', port=443): Max retries exceeded with url: /api/logbox/oauth2/autoLogin.do?appId=cloud&version=v1.1&clientType=20010&format=redirect&paras=E19AB7861EE5FC32C4C13951EDB3DACDBCEF66652235B6D83D2258CD175A39054D0DF38894107D2A2B07D67B17628134465E626A3CB80F30AD7569DBEC26F4CB82252F42F61229D04CB9155F00016BB17180793D510C04F721150593E6CBDAF93EFDF1B6386215F3DF397FE95D9668B31CEA52E21DF7C24D62705E6D47CE888C2FB52785286BA2718284046E048E990B14807D85D540164DDCEACFB776C085F320BD6E99B9269C7EC587A622BF3556BB7666A708F004A3D12A253E3D74689532C39E1C18D6FDA36B3FC466EECC39A9287A2D77FE206E3B13F65F438BD66D243DBEC8695B78AAB2BCED6CF1E09608ADA6B5B6782AB1DEFADED535177AEC4EE60557B9F3D16A48B9796CB1F0D7CC4100C4F6DE97142647CCA3431435E13BA3D17A2AFC5280ACCD74DB44AB7CB7BC632CF1D151EE7F33EFD7D960195D0CEC9A6B112C0FAA90F87688D7AF57A4CB5157C4E9D91BB478A8254701E1123C972EAFF2FA055986E2C6B33DBD4BDAE6F69711A2241F792B9074661A6D0CD6C7CC17E928D58C9F0ADC67DA053E1EF0B7E50D35E2B22221375351D47C261394C4353FBC6D8A5800935EB433E2ACE0E75B55D87BE7217B4CC1B47072B411CFB6335821A29A7F2CAA9E913289F5AE309E7F94818825A4FDECA8736ECFB587B4A5ECB68DAFF440DA2D6371B6DA2E977FA3E0878278EB1A95E859FF5C6C3ED89D09D11016D674E7ED1B0E306CAC4A7B2715A3DF869D4292739099319C8DD8FF&sign=94AD052F8284048AF591225B8FD3EC92D720D81C (Caused by NewConnectionError('<urllib3.connection.HTTPSConnection object at 0x7f7a26c3c890>: Failed to establish a new connection: [Errno 101] Network is unreachable'))
### 执行结果
- **登录状态**: 登录失败
- **签到结果**: 

## 账户2
登录过程出错: HTTPSConnectionPool(host='open.e.189.cn', port=443): Max retries exceeded with url: /api/logbox/oauth2/autoLogin.do?appId=cloud&version=v1.1&clientType=20010&format=redirect&paras=BF360156BF8DBBBAA04C51E340D04E222FB9159F3AC307DC13A76CD8C4D5B0E894B4F59268087B00367551F06D166CA74BD219A6D8AD9DD9096E4A1278BAF21B8E71664FAD9362E342A3463C793EE7AA3E214A26A0402CDF433A4FEDD9CCFDE95422ED7B8EE1D3247D0598DEC13DEEA99996B88A77C5F803EFEC70C8FBC5F1C406B2D59108340E4B643A169F821BFE5D19EF6D020C00B6547044C952765489FC7133CAAF1B6AFC7AE14E2F35BBC0D7987535B9B4A9A417CD367C8E2899A86522B77F1C810EF2AC2089A8C71193ED4EFBC97A4EE4C070BF84A9DD4B207ECE2817908D5B872D72594D0D4BAFE5FDBA0B6BE5AAF369CB9F2D893C8F6F4020450E898CA98BFEAA13E116DBF908E3E56070359044D0D9ED20EB1248D0178C72F5067BDD3B5647255A20E72BEA3EF3025981903F16D800C0CCB76A829CF82595164326CAB7ACCE7C27F6C5C28D1F9EBFD179991444CBEC55B455A73F10A916CC0B9E8DA3C5F3570ED6BB05E472571F0F281528B3E3B77E1BF620126DED560EF8A7039D7F6A0F24F06E2B6C1CA9CFA49D162A14C5B56EABAD27330982ABFC64DAC77AF4F7526C6FCAF4C1B43EE0C8AEA9724DC8D4A553744626AD1FDC386C3EAAEDE032B60D87938BF7E05655ABFF265D8C3EA80B0B23BAB79CF06EA88D1BAB530F2D38BBB8619C0508F098C6B9376037AC882CC4089AD43BA3D6BE9615A2064783E3EF75FB955352367C74267C561BCFFAD85BFFC5D547FE0122D4&sign=A7D4CD0A2A3906B793A331C533348AD621A78F04 (Caused by NewConnectionError('<urllib3.connection.HTTPSConnection object at 0x7f7a26c40090>: Failed to establish a new connection: [Errno 101] Network is unreachable'))
### 执行结果
- **登录状态**: 登录失败
- **签到结果**: 

## 账户3
登录过程出错: HTTPSConnectionPool(host='open.e.189.cn', port=443): Max retries exceeded with url: /api/logbox/oauth2/autoLogin.do?appId=cloud&version=v1.1&clientType=20010&format=redirect&paras=88173DCA7A2F2CB45F245367C1E6463AE92B675161FE5D6ED35C08AA3A6C46068AFFB2FAA0566276892B91ECFEDFC2C9C693337691E2E94C90F8264CFBA336001F7569A9A06AE5B95225B0DD0FD33D142C3346D7EF5BCDF8A5E67C5B53F77340247ACAB5DDBD9D32C501F7B5E803ED21FA29D4A11681080AC39C4A81588E2B44FE0CB023C7FDAF4442F8C771E095872158FBDA3F409BEF17639240156402E3CC217E7671836D09A5B3543E43C26848C7FA91C3567B0DC0B4FE9A2343318A4F5C59766995EC43E1D3BE6262EF9AB4827D65AE333BDB7133B477087A2EFC55498D816A59F977F5AB9E34668E5F1AA15398D05E3009F02A0350218F3724446148C163E8D6A4B36EE19B1BBA7A41F7C61F6B9D00C674AB5EB50488ACFECA754D56B30B1D49CF680B7371C6183F2EC2DAA90AC994144CBDEC5A35377D270406EADD8EB6C0333B643F3B04319D8CC28C0788F48A9BD6D1C69478F92FB255D23C7A792D9E1BB98C95411F74182D0E766389BA12701D937CF7FCEEC5A587433343341ED8AACF846E211903508B603ECD4FEB0DA8E67E698C4439AD00598DD49C86334980CFD212F3972FE645C42CC13F2E2C9DC1400F7B5877F60AD8551AD1C42F1B633182EFC7622E7BF5085AAA9CF25E94043F1B66ADF9B837933C6F8DBCC8B3F89FFF9DCA1F1C1AEB73B1F40EA36CD03A521FA0D089E98FA8E76E0043A2D6B0AFE354CA077E582018B3C3A7F64F1E1C89009FE4DE53473C164216&sign=5C5149374F6E5726B4A096E001B4EF217CD16CB1 (Caused by NewConnectionError('<urllib3.connection.HTTPSConnection object at 0x7f7a26c2b4d0>: Failed to establish a new connection: [Errno 101] Network is unreachable'))
### 执行结果
- **登录状态**: 登录失败
- **签到结果**: 

---
## 执行统计
- **结束时间**: 2025-10-19 21:53:57
- **运行时长**: 819.59 秒

✅ **所有账户处理完成！**
