# 天翼云盘签到记录

[![签到状态](https://github.com/mfvi/189pan/actions/workflows/main.yml/badge.svg)](https://github.com/mfvi/189pan/actions/workflows/main.yml) [![项目主页](https://img.shields.io/badge/GitHub-项目主页-blue?logo=github)](https://github.com/mfvi/189pan)

**最后更新:** 2025-07-16 21:56:04 CST

## 快速导航

- 🔄 [查看Action运行记录](https://github.com/mfvi/189pan/actions)
- 📋 [查看最新运行](https://github.com/mfvi/189pan/actions/runs/16321485214)
- 🏠 [返回项目主页](https://github.com/mfvi/189pan)
- ⚙️ [手动触发签到](https://github.com/mfvi/189pan/actions/workflows/main.yml)

## 签到详情

# 天翼云盘自动签到抽奖程序

## 执行概览
- **启动时间**: 2025-07-16 21:56:04
- **账户数量**: 3 个

## 账户1
登录过程出错: HTTPSConnectionPool(host='open.e.189.cn', port=443): Max retries exceeded with url: /api/logbox/oauth2/autoLogin.do?appId=cloud&version=v1.1&clientType=20010&format=redirect&paras=9F11E1DFB59A01F5D55D34F4470F361894B612A7D91D017C07D4F0CE3559AFD99B30ADEF9E55B55BC2868EA963D74AA37B6E21E481147689517CFCDC309E19EC5251AADBCB198153F02F3221EA498B46438B689F1A06CFD55645B796A420F8F41C375B1A175F8A44CBB2992E2C7A3AEDA6A69B528BC692A57AADA58AF7216BE13E167F697F8B71F84B6C98E3180BA914E051B202DEF0CF1FCF41BB7983AF5E8B9C900A5627520BBFD159F8A30074C9F163E662A18FF1DCBF0E6B017A93238ADD11F89B68D989B0378EA9FA64F08FBA4C05DEF3366ACB0B130C73034AAF7EE338920EDEE5609C79AE1E9775D3F8E503D8EC7E755C775B2AB6DD75F8C044F16415B5633E731D9EC1E7F31F44CCCD44C76C5975EA5BB590D06FC8CD0316A3883B99AD365543D4BFC841148000ECFCC3AB906B58CB14A8401B96379EAF0C601339D7451E8F0105090575877B78040728969529EC99F6E29DCBD59F79EAE582203F8429941E2A2951E556AEA09923B39361CAE8362D6C2F920C7F4B5667C2BCE95A115B8EAA9DCDFE9183822370E02CDF82C00FBBC18C5C67A36140AF430550AC91D1EC62E451459AD317BEB7C7E0F393623554B502B7C383FD0D35C00F912E0E4F5C07627357EA58324956B17FBCF195C453991ED0EEF7AC84932193A49F31365C48421024C55B6EA6918A7FCB43BC54831466F380A14054318F799AC55ACF80AC5C12E889997F3E5618CC935BC372ADCEDD1B7E180BEE7BBF21&sign=3D49E9F9D22C4661BCE4F553BDB17AF5C95638C2 (Caused by NewConnectionError('<urllib3.connection.HTTPSConnection object at 0x7f23beae0950>: Failed to establish a new connection: [Errno 101] Network is unreachable'))
### 执行结果
- **登录状态**: 登录失败
- **签到结果**: 

## 账户2
登录过程出错: HTTPSConnectionPool(host='open.e.189.cn', port=443): Max retries exceeded with url: /api/logbox/oauth2/autoLogin.do?appId=cloud&version=v1.1&clientType=20010&format=redirect&paras=EE75E16678252B462758B2F4B7C52CD99E70D793A1CC587B2B0D82C857A65D7BAE2D056074C75F6C3466547E43D0B38614E9A16E02532BEE27EF82187056A109621F17882C1B2D14938665BB27B24DAA74D2340BD1469D29CCF1F2D2A1DEC55AE6C81D704C8A2D2EDB24E15D11287A61F5E17D38056757DBCC4807B0AFEEF00E70411F2AA4E00E29D6F696096EB1EF4E76D8D6294826D1BAA949AFDB4A22E5E7744B80C42F50FE2D079F4AACB8AB37451E977A819613C5E13DCC0E9EC95D67087F85797A0D754B3CE862AB839EE70B4185DF1594D9C4A9BFA469B4BD8660ADFA5806F569DD95A3EDECFD4B217772587C3C38CB24D99F8A7A69382C162DF2E1741514D7D7C192A5DBFEC8745F760E146EDA402F5B235180744EC897BE68BB198D54B77DFA0E5632A00FB2B68FA5E26D6D356AF747A04A31EDA7B80BD0F6744A9FCED40B25D50992A8D1A755C1A3EECEEC87B7639F60F7CAD6BF6CE76EF85AA6D24208302CA011BE444481F45703A38716B527B173D5784E4E7DE6E2ACA9F032AECCB74E6963D5DCBDD359602F2664699FEFE73BBE66D74837A9E464748EBF5DF0A9FD3C8F5CE3E87F1FBB6CEE3416038017C8497B65FFB0A00EAB5C474C807D07AEAFA6D78BC42CD3CFAF8D41BEEF410D7CA06BB7929D95386A8DE7230179AC81393F5831F6E563E31752057B6CF1ADC156437A3E1495D33E86DFD4E917FF5EE019EF45E72C34EE7FE0CB295D18E36488E99C79E35E229D26&sign=97AD853AF13A09461980703AA4097B8E9799C3A7 (Caused by NewConnectionError('<urllib3.connection.HTTPSConnection object at 0x7f23beae8150>: Failed to establish a new connection: [Errno 101] Network is unreachable'))
### 执行结果
- **登录状态**: 登录失败
- **签到结果**: 

## 账户3
登录过程出错: HTTPSConnectionPool(host='open.e.189.cn', port=443): Max retries exceeded with url: /api/logbox/oauth2/autoLogin.do?appId=cloud&version=v1.1&clientType=20010&format=redirect&paras=0FBC05B1F69E2A52665FBE4CD37DBA8D62C7F034363F1DA4A4105B1C4B7D794217D0D6431ED062EC2A5A835509F502F505D8CA67B984D63ABDADF0CC5B5889473B7F42B314D7D4AFBF34AD54F3F6E4AC0AE59978C504A5424F8A430B589C4D40748D363D98DB03380E52382B54E49E881B434903B3CBD788357A9E8BAAEA2F93A2E89A9548FEFC9D9AF5BA347D4331E48C3F9FE84D206D9650B70ADCCB26995878818E878B0442E1EE1BFDE54DF44C7FEE3DF20D2E0496A05B883D6AD5F72C3F8E6CF436F4F6BA5417501B5A55A4AB8BD598158E3546C1544A51E0B0BD1764D418DD8380901FE9453A5B8BED1F1619546BB017DE51C898F5CFF0B7D74EB7573B174CACC3E32063B759112C8261DC48BCFFC3F8674612E9492B1CB874222E44A6FBBA60AE6863901772C01DD235FC65A0200E8A466402C08A0407E18E89D06A65E2A88FF8DFACBA354467466E4D786504FAE07C653091A2195B0B311A484CBDE8FFC128F136E5F2DFB4A48ECA174AC6769C0AAD5CD8438D5D75DB0FCB36636224C7CB368C71B1ADD429FE0627CC6C264D1EB720F2417ACD199778C409340A9CE0674C594DF7E97000377E69FBE9FA2A7CD4B9033911FE0B36EDA16E849464D62B18A4F01063F0695949F0070330A2D3D6CC87A612BE9CC66D03D1394D2F635B5BD03E01812397ECA444BEEA689250DE289E79E7B5925435B91A787FF1E087685457ABC0F6122CB80997A6503CF3234E087EBC134A4615DE3A&sign=4E920C5CCE0ED24656FB26E31B9945FFA55E277D (Caused by NewConnectionError('<urllib3.connection.HTTPSConnection object at 0x7f23beae3d10>: Failed to establish a new connection: [Errno 101] Network is unreachable'))
### 执行结果
- **登录状态**: 登录失败
- **签到结果**: 

---
## 执行统计
- **结束时间**: 2025-07-16 22:09:37
- **运行时长**: 812.48 秒

✅ **所有账户处理完成！**
