# 天翼云盘签到记录

[![签到状态](https://github.com/mfvi/189pan/actions/workflows/main.yml/badge.svg)](https://github.com/mfvi/189pan/actions/workflows/main.yml) [![项目主页](https://img.shields.io/badge/GitHub-项目主页-blue?logo=github)](https://github.com/mfvi/189pan)

**最后更新:** 2025-10-22 10:58:31 CST

## 快速导航

- 🔄 [查看Action运行记录](https://github.com/mfvi/189pan/actions)
- 📋 [查看最新运行](https://github.com/mfvi/189pan/actions/runs/18703934696)
- 🏠 [返回项目主页](https://github.com/mfvi/189pan)
- ⚙️ [手动触发签到](https://github.com/mfvi/189pan/actions/workflows/main.yml)

## 签到详情

# 天翼云盘自动签到抽奖程序

## 执行概览
- **启动时间**: 2025-10-22 10:58:31
- **账户数量**: 3 个

## 账户1
登录过程出错: HTTPSConnectionPool(host='open.e.189.cn', port=443): Max retries exceeded with url: /api/logbox/oauth2/autoLogin.do?appId=cloud&version=v1.1&clientType=20010&format=redirect&paras=B2C1396724D13A0A9C42B2117702863E262E4C7563F56B1CC82E4149D2BA4261B74424905245D2FE557512565495C8AE8298D2A7094F5C5BE1D6DBB9A50E3C58B746A51AD1281344074FA9BDC1CEDF2C36C40DB2F3D31505E8C97F764BFCAA337AF1476D20CDCF7B321B8AA331FC83D3A3A09FB215339F5DF610E8B2AF0DDE33A6096F905EEAEB0FB2EE511B9152F6CAD14F0675057A7B0C44A65ED2070EDE26A99951CA6613C3EE605F205C96A7F859A79FD2A64DD6CE4ED898369E07D1BD9317D01AAF1338679D474F09E2049AE4EBDEAEFAB4DF7EA5E35D6A75D479FCE9A910DAAE2CDE0C0B6D33ED82D1CABCBE4C91351714FB8C5641C4379A8D91D66BB2374DCB497621B400665682C51EC437FA0CA70BD4BEE4CC7D74A6B93CE4FF9BB5696F33DB26A95942307366A1ABB3C61EC037A61327006D77B63F643DBBD21D1E6319AC6B2BEDD82FC5EE94325E5AB55368A46E4AC0B752AF92277620F635C9851FD57E22B937013EC93632EE2FE3E7008EB10BF380E98DDBDBB5E5F88FAC43DCF8C53BC2AA5A46710E57A4E078F78376D29A6A632AC173495ED3C0C6960807A1989117E314A9AB021E03DA2F9A46C93F6A6BA9C62A74D1637922A0C90805D25C630A5C3B2F8D40B15494A19D8026A559C9FCFC4D8609D05A61913E88BE305EF1F1453329E1FC92B0B9BBE8FEE3B01FEB92F1F613FBFE00F287ED8B10BF4EE97A75A78F697528A1C6A5409161ED6F367F72AA3A068CDC9B50&sign=A09F62C66EC520AB8C9849A414F48945764B2CF5 (Caused by NewConnectionError('<urllib3.connection.HTTPSConnection object at 0x7f6e4e768990>: Failed to establish a new connection: [Errno 101] Network is unreachable'))
### 执行结果
- **登录状态**: 登录失败
- **签到结果**: 

## 账户2
登录过程出错: HTTPSConnectionPool(host='open.e.189.cn', port=443): Max retries exceeded with url: /api/logbox/oauth2/autoLogin.do?appId=cloud&version=v1.1&clientType=20010&format=redirect&paras=B70CA5CD7DB73F8B87D1CA784986C4B6FF7BF7CD6C0D02E9167F68944076FA110CA2C08AF56FD3761C61A5F6C3B0B23AA024D708927F42EB6961E2ADC75738EA894F63A7D33BF30BE4177D3E230EBDA5DCE611A3BCE45C45213C8CD86A5C22A551709BDDE2C2ACFE528F22B124ED9BE560A2CA99F4A6B34B4FDBB648E22260F9FA80685A826F4F4416E1DC87BFCBAC96112F094BB7D552860C6EC0DCB64854700C48D2CADD9BE55F7F32E9BA33D2652626FE8367F5C29B92B67EF45AD6EC1527AAE3FD6C6897245C0CC8E250C42AFD67BFAB080574995D12ECB75C94B8B529F1D602DF6529C6AA89A78E4DA87E713B98E705D966EF56381DF9F0E83E42247990EA894DF0D610844A745799367D03F0C17163596A69A7D12C580F74610F03E9FEBAB39D299DE01A0B03088EED65382F082B03B5B78BEE33BF251D672E1F45AB2CF831AAEBDCD9BD874F87D511F134B4C96F750A612DCD71D75E5AA79BDECCB53B0E27D40C22AA30DAF28C3AA3849B40B54E97B3A9BDAC85EA40613394B46F4515DE1A82817925F86DA1E765DD1423D9791B18FD87389F10B821A9BFCAE124CCA050C4FA10EBCE5B4A1D1C6F28F572D4A33678AB918F7274EED84DB96EF92A626F71378D8BC048728228EB4D48674C251FF4A180552E9F436BFFCC432404D65CA5C15570DED0CBF024E04C76047959C7D0F0013109888894FBAC098B0FC52C6C201FD951F07E14FE85448BFA0A3AC83E2E85AFDBC6314333BB&sign=571EB49F9878E6F1566C7EE0BA2D2EF305B61151 (Caused by NewConnectionError('<urllib3.connection.HTTPSConnection object at 0x7f6e4e774110>: Failed to establish a new connection: [Errno 101] Network is unreachable'))
### 执行结果
- **登录状态**: 登录失败
- **签到结果**: 

## 账户3
登录过程出错: HTTPSConnectionPool(host='open.e.189.cn', port=443): Max retries exceeded with url: /api/logbox/oauth2/autoLogin.do?appId=cloud&version=v1.1&clientType=20010&format=redirect&paras=EBA88DBD87160E8A3793D421DFBC2FCE6F10224D75EF3DE71F5602295311A73D8FA666AEEFBF2F550E433153054399876D53B27AA1452DB79C5D1750A88EAC1DF32067FB2454CC54EA170875DBCCEEF31FAEC1069839D39C073CA4F73C8D8BD867BC26FCFA5F0164C0412DE01D89DD87CFACFFAB2A90821E7DD88B3F0A16C531D713E89F754677AC5AE87D15173D38803DDA260A32DEEFAF8BCDCCAE1C03D697AFCD3D39AFADC8B68AF478016DB529270BE88B192E3F83F31A2EB77E96B74304A3389660FFF898A7172020EC8099A4A5FDCF5DA5B74572AA6C372E2A08C6F4809AA72496593E13B48AED157EAB8EE09034867DD3512860836640069FAADABB252EE9F9FBF4387C07DC022105701E7F3E3B317D50B7A9384DE7B567082C11495F112D919ABB05E186099CF1E65DBAB33419102BB550DF3F0554A7C1F82750F42116DB818DA56530D32E338ECD6DDD31980D04C9AF5FDB4A8718533DCACF435D51D310203D61C204A808EC0C51C99507658947906D6865D758B8D8311D87726C1B8C9CA93F867C9C79C484704C0D014E2878FEDBEA687C5E09C8EC570231EBB9D34E0CDA5935841D923BBDB42C1AC29E1238C88780434FCCB272145D3CFC75F65651269A2C1F8116246AC3BE66499D3E5272407A02C70D43FBF47BBF924776D03CE6138202E2EFB9EF3804AFB79E37B45B55CD70C0FC054E74EDB2728A22D912A5A4D82B75A438DF9021129963D6C157F275949C55B5B4A593&sign=424B805339137FF22D2718A8393686C753D9B0CE (Caused by NewConnectionError('<urllib3.connection.HTTPSConnection object at 0x7f6e4e73f590>: Failed to establish a new connection: [Errno 101] Network is unreachable'))
### 执行结果
- **登录状态**: 登录失败
- **签到结果**: 

---
## 执行统计
- **结束时间**: 2025-10-22 11:12:04
- **运行时长**: 813.10 秒

✅ **所有账户处理完成！**
