# 天翼云盘签到记录

[![签到状态](https://github.com/mfvi/189pan/actions/workflows/main.yml/badge.svg)](https://github.com/mfvi/189pan/actions/workflows/main.yml) [![项目主页](https://img.shields.io/badge/GitHub-项目主页-blue?logo=github)](https://github.com/mfvi/189pan)

**最后更新:** 2025-10-15 21:48:54 CST

## 快速导航

- 🔄 [查看Action运行记录](https://github.com/mfvi/189pan/actions)
- 📋 [查看最新运行](https://github.com/mfvi/189pan/actions/runs/18531135271)
- 🏠 [返回项目主页](https://github.com/mfvi/189pan)
- ⚙️ [手动触发签到](https://github.com/mfvi/189pan/actions/workflows/main.yml)

## 签到详情

# 天翼云盘自动签到抽奖程序

## 执行概览
- **启动时间**: 2025-10-15 21:48:54
- **账户数量**: 3 个

## 账户1
登录过程出错: HTTPSConnectionPool(host='open.e.189.cn', port=443): Max retries exceeded with url: /api/logbox/oauth2/autoLogin.do?appId=cloud&version=v1.1&clientType=20010&format=redirect&paras=530A0266A9B6804A5427AEA6CE216D3CB95AAF493F56BE51979247EDC270F77F8A0596B6095F18957E923441F289E638924608DA846E7280568887F1F604C166BCB3ACFB6EA8936456B438EB13AC3563C634C7E2A956E1B1641416CFD7BC74F14BC970C323441B79C19DC33AEA0E7473C7FF815D8632FC78D5FAFEFEFBC64978BA812F0A40C9C761A5559E0ECAF36743DFF2F783BE8FC8035D9FD674EC837AFB2CD795ED88ACE777DF3628B51951A1B2A3F294D333179C8B5F136B1F4771A74AE9915E93ADDDA9B4D045B49A830922498A1964DF77E2EF8D05A4C9268250B95AC167B3ED1CE5A8C03AD620E3DFBC30D1710F119DF28A37003345F4027F14CBE39ED7EAF814E6AB0801799395C11801F43E2AFEF85FDD18F6A4175B4365547CD622147927ACEC4C34197D4C2F17509D1CECC089C320051A4844BA7913B2DFABFADCF6F5731A6B9965AA50D919B46589A70E947951E441C55A74DECCAD177DAB4AB943A9AF52F55C035F96C37F6858D004764DE0F7D5B0AC4896E53EF2EAF3075A625B22C4A6E2E99FE4A1A13C20086FA12129AA7AB16B1F6FD1F72B6E7E94548D9AB6D788E252F160B131144565643C7B15EC82E4D323CE916A78C6AFB9B933255775F7B75E5323F6FEE35FFCAAF4992B9594400A29988C3F70795834AE78678F64833B5B4060E8899F1B2CD65B4FBFEC403CCBD294B587E8B7D6A4A13570A0358CF90B70D852235682FA426FE0F455A099DFD83E65721FC8&sign=D2D958140004F3C63A85F864FD7131E1ABD2AAF9 (Caused by NewConnectionError('<urllib3.connection.HTTPSConnection object at 0x7f605230cad0>: Failed to establish a new connection: [Errno 101] Network is unreachable'))
### 执行结果
- **登录状态**: 登录失败
- **签到结果**: 

## 账户2
登录过程出错: HTTPSConnectionPool(host='open.e.189.cn', port=443): Max retries exceeded with url: /api/logbox/oauth2/autoLogin.do?appId=cloud&version=v1.1&clientType=20010&format=redirect&paras=E9434A070B4BB4D49C10F0C569377EF4DE29475192F8B6ED049B7DA677BA1BBB2033BC400F328A0655D136E6DEEF74B4F5939CBC9A5F6D315200668C996B77090DFC78E995640A8603D6494CB94C0807C0AA39B5D08ABC5E7AD4781984782DB68A1EA553B005D5F568E01772223AB04B42B89424B66926FC47B071E8BC9D0F7C212510A68955C0A578D29F95006CE43275BF34787F725053337B6922AB32247FE00D7CCF870C5FB96CAD6B8001AD225FDF529ABD0C8C9B3B63FCDE1F0D5D244E3F8050FF377F2FB6015B55C9D50DDA60BF14E849E908C328FE5DD6587E1F1B295DD482A8CB3DB3241403A48105125129D53157B123069FB24E638FA638AECA43126569EA8C620A8ED911B43C40726ABDA54B96CDA6829270926DCC63394BEC89DCB57519247185AD06EE2CFA7A56870102499697AFFF2FDDCA9986C89391A76B091C5A915E3C2ECE7D00020AB1704CB7357E2B0BC5E783A2873D0BF1BB7E208664BBBA014141D664EB1B09FD58CC5E94AF2B3D11999517FB60CE6700C51B9C9B89F54BCC0A014F482954298E1956A5BCBD9E01893F3FFE192CC243D511282D3C0F1BF3E3B114BA774ECB624D84E0749F7C8A38D07F241EC3484644D6AEFC43F14E5376F5DC4E53BC55B6308B99142DAFC4EF114CE89EC50EA8CEF88DB9CB9B7A8E1C41873F3BC30B037D24FAA8F27B8D1213560AA4A03D6B9B54B210333CF362467EBAD699521A5C810A8664F1DBE983F734F627630E5D97&sign=A976E4E5675C07254E9DF7CB683BB4B9B698A2D3 (Caused by NewConnectionError('<urllib3.connection.HTTPSConnection object at 0x7f60523182d0>: Failed to establish a new connection: [Errno 101] Network is unreachable'))
### 执行结果
- **登录状态**: 登录失败
- **签到结果**: 

## 账户3
登录过程出错: HTTPSConnectionPool(host='open.e.189.cn', port=443): Max retries exceeded with url: /api/logbox/oauth2/autoLogin.do?appId=cloud&version=v1.1&clientType=20010&format=redirect&paras=13FDB0125A315000C8E747C569139747F416B4F3568B1139A1EA6602EB3ACC8BA9716F322EC9C7DAFAC87188875083CAF3D5C485C6F839E0B5E3F7536A51CC2A16F84B476F12B61457612DE2F77E650C9CEDF8BEE678450776DFFC26B1F7510669BA99BF64C72CB346EF874C9D0A5EBD44144F91FEAA5C3AC1FC7BC6BF9C7811B1EDD4F54523D45C6DF1D212F68B100C45B16D48BA18E7F5646034627CC53AB183ABC554E2973EFE54F36653F8C9A4E645CAB6548603052F7897DD5005E0D095FEAA05D8FD98305A5790FDABEB78048D8BFC8702F9209D91F09CE9D86538D7AFD698E9443F213E3C6B43DE9C153982CC5D9C8D8CC9498DF9FD55C3049A8F3A9E7EB602A3E534B696FE568A6E1726C019126A9F8ED135CE44891983C9A939A1B268491FF6F06C4362F6D0B152C463B07413DAF74486D3519D3C52877278315108329A2A26C5ABC48E29D0B0D33BD84D0D331F87F8ADA51E483D44AFA69B68CB81DBAD2F3F5897C1937BE8E0E7163AD69544B1A80A39B5F20483130BE720267D6B43577E34F42ABB8CD3A7F077CDC0F973B157E3D90BF7A66DD6DE39D95AC9EDF22B41D49F4864D4B7E34874B777FB6A9DBFFA4E4D2D4720435A53810502C51C7FA9CCBF3560A828E53B9B0C3219A5A704DBF020575F5D7F13358FA47E2619633F970E1F99EC59E5AE56C902A27AB64DF22BE8C46D6ADF5649443BD9F67465CC0F3897A9AD4BF2A2A99C39193C8A74A0E0F68D4029528363B0&sign=A99CE7E23DF4A0BC7C53EC073A9243004F616BD3 (Caused by NewConnectionError('<urllib3.connection.HTTPSConnection object at 0x7f60522e3850>: Failed to establish a new connection: [Errno 101] Network is unreachable'))
### 执行结果
- **登录状态**: 登录失败
- **签到结果**: 

---
## 执行统计
- **结束时间**: 2025-10-15 22:02:27
- **运行时长**: 812.60 秒

✅ **所有账户处理完成！**
