# 天翼云盘签到记录

[![签到状态](https://github.com/mfvi/189pan/actions/workflows/main.yml/badge.svg)](https://github.com/mfvi/189pan/actions/workflows/main.yml) [![项目主页](https://img.shields.io/badge/GitHub-项目主页-blue?logo=github)](https://github.com/mfvi/189pan)

**最后更新:** 2025-09-10 21:43:41 CST

## 快速导航

- 🔄 [查看Action运行记录](https://github.com/mfvi/189pan/actions)
- 📋 [查看最新运行](https://github.com/mfvi/189pan/actions/runs/17615773475)
- 🏠 [返回项目主页](https://github.com/mfvi/189pan)
- ⚙️ [手动触发签到](https://github.com/mfvi/189pan/actions/workflows/main.yml)

## 签到详情

# 天翼云盘自动签到抽奖程序

## 执行概览
- **启动时间**: 2025-09-10 21:43:41
- **账户数量**: 3 个

## 账户1
登录过程出错: HTTPSConnectionPool(host='open.e.189.cn', port=443): Max retries exceeded with url: /api/logbox/oauth2/autoLogin.do?appId=cloud&version=v1.1&clientType=20010&format=redirect&paras=420CDA7DE87E143910C301B55827C04F9C4EB94FEA785F7E45516450AA96428C5558354F8AB1A42CC51A74372174E6885D3EDE8261B255975100F33B78DE2B5B185FCA7FAFE4164F9324B91CFECFAEBD54DB234B9574DF428E7824B010755DB85A0C3CCFA72DC5398ADC03FDA3C1574B10795431755D1CB6DC49D3A9F915AED6318A40FAF71A72584DB0651F05DFC0DAB81FC277EACFD1EB78364FBF13BC883267F3229446F9E729ABF84048F3E7BF890820EB68A58F6E884E443F60CD7D97C8AF2CF06C5558F28C37475F4122FB75713E43BEC4F02DA3D12D512FE95423322118355C683EB4FD33BAA328FAE3F63F45AE5F55309FF7C59FC956D03173F838B2BD3445205AFF5877E2ABF0F798D2E4F531EC8601808E5A4764F45D8FC1EB8C8701BAFBE446535B3F3B16A7FE333C5B8B670C74E6DFD950F81570EFE6FE9456B4C234FA785F2D873339A8051FEBBE49C5627EB51F9CA241165C25CEA661FB1110281A557C38ADB7CC42F38CDD56B89E2E7611B3990DA56AE6D10A8CBBF1B997A054E6269C6C93D55D87B81BC3EBD904606012777524316B13EF64D9638D832E59DEC2B64ACF77C94CD1021552808C3B06BAB78A39081494EDB37D5160031C13B72DB761F8CA6E21A9ED42DD3651F7D8603DB5308D8DBABA667D5303252A103474B2F9B1DD6CB695D6DAE26D6654D5A887B07C03FE9D3216FCE10D3F1C41154BD6122D0CAACC9EF54CFB0452CC1B6590267FFA0364E531AAF9&sign=784A7172FD3812B86D2C20F28FAD49A71ED3FEF8 (Caused by NewConnectionError('<urllib3.connection.HTTPSConnection object at 0x7f1db1a04a50>: Failed to establish a new connection: [Errno 101] Network is unreachable'))
### 执行结果
- **登录状态**: 登录失败
- **签到结果**: 

## 账户2
登录过程出错: HTTPSConnectionPool(host='open.e.189.cn', port=443): Max retries exceeded with url: /api/logbox/oauth2/autoLogin.do?appId=cloud&version=v1.1&clientType=20010&format=redirect&paras=8A22BD6680F9C54911238003CB4030C5DF78B5FD73566CFDFE4E63E29826E3EA19A36E5B4270D875B49D6E82E3C0165D731559E4CEE2A6E6798E2C5D78540F9D102CC2D666B2F2CA5A5AE5CEEAB9D6442664E2AC0CDE3C9099A5B29A4824DA56675B1E5A04283A80148AD62EB0F76A387A26D235EBFCAAAD9B5D7CDE7EA472ECF1BB65D336FC9CA2BE0C80906B8378A667316FBA358A0D03CE2CD45DF6299F9A75ED063E33B0F415D89D0FB959171952CFB9AD92B053F9FA123B1CB88CFCDCFBB6A50A3F3A67B2F16850A4DFB3C6076259E5579609765821CDEA0B797B66A839274DE9A2EFFA223702EF34DE8450F26F46380F7C450410567C27DF69657D6F356E1BF0F35DB70D1AC498469750E6BAEEDC55AF561EBED5E9E2733FC2DFDD4E03F6C2415F9749131AC56B3D16BDA2F74A1B4D0BFBED3F02CBF2F2B0BE16420691DAA655445E1FD9A11291AA3D6999C04725DAA25B60B4207BA43B574080819ECA40094BA2E5A4BFD51F89BD3AADFCA32C7D3936D4DD83E6F111330003032937E4CB4C7ADF7A4E222C70B54BEC281DB026A7D43D4FC76C201F0E82155482A8FC838CB3949CF33C6EDFEB8AC3C2ECE997B87FD80279A292CF8C938B0670747A6F12704B3D64697E4D240E7361689DD4E8DF59DA96AFF33344822CA67D749A80DC355DD3CBF4FEE82BA116AE91E79DBD0DCC586750390AC0E94646E9D679AD944A4BA1843C3E17EBAD1EF2C5F6DB7AE90C92FB3176D7AF2A11A2&sign=B51FD2F5B472500C33D29C415767C4E216A5DE0C (Caused by NewConnectionError('<urllib3.connection.HTTPSConnection object at 0x7f1db1a0c290>: Failed to establish a new connection: [Errno 101] Network is unreachable'))
### 执行结果
- **登录状态**: 登录失败
- **签到结果**: 

## 账户3
登录过程出错: HTTPSConnectionPool(host='open.e.189.cn', port=443): Max retries exceeded with url: /api/logbox/oauth2/autoLogin.do?appId=cloud&version=v1.1&clientType=20010&format=redirect&paras=5419897A64D97254316609BB3BA4C11223304B967AC8F6D63E106BDB53935BA16D6082D256AC31778EB5D71B62FDBE880500112CC5CB6D006C7AE660ABE9B981A9A5C11BB99D017417BF530FFC161C61BFFF1265664E6044DA6B517EEBFCFF152E31D656716DE9D8E5E16BC48595804A661D0C2B69F35C6B50F0D07DBBE3AAEF191EB036FA1FEB337DAEA2D8E25824D9A16E2DDD457F7C96191F3C69BAA2C4083D0DE589033FCF536866B62EE4F113E76299E0CBC04D3EE028C909FBAE3DD0F275F9E6AB7A38230DD44B8282326D8D3925C4072E3F4A2DC93AABB87D1B22ECC3FD33F4A7B291C33E30A73EA7B2436C0830895CF1184FA7314AFAB50BB1BE33A0A05535CF66CF347AEDA729437E56DC7D3A7B97B5A9C14D31701ED1EC9DB95F482D2F6C718F9988091DC8B26D5886E42961ED4C2134EAD795CA1E31F2F29DF8BAED06A09845E9B4474FDCDB4E79464E6D58D0A992CB0FE9E854BD59985FADC6889963A1071502A9D7998FC59403271EA590629FCECF49E9CFAC84AE6BB7568BAE896634D60B29E373AE9873ED105C62615E8F5F0A63FF9964A32EC844F702E5D6CC8DB22B5FDA49F92276EC6484C6EBED72264BE222DC93354C5AB311015B343C018C6A072C337AC38655F058A6113B342FF6F57F90BEF5CB86719A7DB8361BDCF0B5BD3007DA6D117A2B41544BAE6410E55566BD6F68729DE90247C2693F4B83B46A9FA39C8325AC929A34EF5847CAF83774A6844FCC6D10&sign=A2FFC0B1A35EF309C5711CBB28728AB4052881F1 (Caused by NewConnectionError('<urllib3.connection.HTTPSConnection object at 0x7f1db19f7510>: Failed to establish a new connection: [Errno 101] Network is unreachable'))
### 执行结果
- **登录状态**: 登录失败
- **签到结果**: 

---
## 执行统计
- **结束时间**: 2025-09-10 21:57:23
- **运行时长**: 822.42 秒

✅ **所有账户处理完成！**
