# 天翼云盘签到记录

[![签到状态](https://github.com/mfvi/189pan/actions/workflows/main.yml/badge.svg)](https://github.com/mfvi/189pan/actions/workflows/main.yml) [![项目主页](https://img.shields.io/badge/GitHub-项目主页-blue?logo=github)](https://github.com/mfvi/189pan)

**最后更新:** 2025-07-24 21:56:29 CST

## 快速导航

- 🔄 [查看Action运行记录](https://github.com/mfvi/189pan/actions)
- 📋 [查看最新运行](https://github.com/mfvi/189pan/actions/runs/16498897369)
- 🏠 [返回项目主页](https://github.com/mfvi/189pan)
- ⚙️ [手动触发签到](https://github.com/mfvi/189pan/actions/workflows/main.yml)

## 签到详情

# 天翼云盘自动签到抽奖程序

## 执行概览
- **启动时间**: 2025-07-24 21:56:29
- **账户数量**: 3 个

## 账户1
登录过程出错: HTTPSConnectionPool(host='open.e.189.cn', port=443): Max retries exceeded with url: /api/logbox/oauth2/autoLogin.do?appId=cloud&version=v1.1&clientType=20010&format=redirect&paras=197752569416A057F9449250CE62BA786DA0B5F33C70E25866434828478CDBAA931C509B9396EB7719F21E95C792B3F4F0A78BE84B1558E79FF30154C3E02E1A9E2E2232BF8BE2D9DC9166B89B476706D3A55EDD9624D4E51352D2870029759C894BD30CE949599CAA9FE9A6D544EEAF4F32F8E3E2DE29E143D4780149E6827457BA05C040A60D875AE2F5AD782FA866E36CCE6EDC9B6DADB55D4B1B8A95848CA92EAF8CFFBC08400DA4519866BA6FF7972F9708C804D169841558CE2C0E34E277406B6512F6715FC002EEF09463F74093DBDE51B9257CF31F2EFF3879AC0EF2ECCA271DC3D0A88D1105B25047FA1A4222C6F9D7FBD2A1B68B4E8E01A75FC6B303C251F098EA6DDD0BB4C35D7F47FE16E1F124C2E404FEF568183BA94BEE72FB4955410449733F12940CDC93C352BC8F99A4B2DC8408CFA21641544076D2DAFEF012BAC5FB146F47D20EFEDC96201B5CEB8BB3A536051B42C0D300A2510CEB7FA245585E338935CB4C36BD1675B2CB2AE9B25542E9A43709BF6E80D9F2D58295A57373E9BA9BF7BE88ACEB6777F3A37692B7ACD4B5EF727A385745CE30CCE97CDEBED501880AC1B4B39E95A3CA517C49E4580D44855257DAFAD0B8445E9431E46055A68BF8A03AEA7807716D0A0D1E8A9A45B021E26A87AAE2554F08F7F8F74A31865071E2EACD0361A0D9B4270F034051B48A1D9782F7EEE26F486088CA89450827ADA0CB6D39E94DFAE02B7624E3D60E8947857D68943C&sign=AE533F47C284CFA83DE97E37D2DA2F09A04EBF3A (Caused by NewConnectionError('<urllib3.connection.HTTPSConnection object at 0x7fe64f3e8850>: Failed to establish a new connection: [Errno 101] Network is unreachable'))
### 执行结果
- **登录状态**: 登录失败
- **签到结果**: 

## 账户2
登录过程出错: HTTPSConnectionPool(host='open.e.189.cn', port=443): Max retries exceeded with url: /api/logbox/oauth2/autoLogin.do?appId=cloud&version=v1.1&clientType=20010&format=redirect&paras=5D5D51EDEB4C6C4DD537219DE0AC368E78BEF64B0F467CF409298EA675C206370C8F9C1CB0B2C613BB431F98FF352D152659FE34EBF1B9EAA8CB1C09C085E8AB15A141B2C5EDD5E2FC8F69FA86F993E06859F05B1739FAEC7F53247FD2E404A079C8D0F34DE10CD15E30CA5E7507D18A6D0ADDAC3FC395F8AD9246DCCA2E59C960F48DDA17034BD525B871D47D67443010CF158AB617D32621BC52E8D8F15A1644C4AADBE8DF82A4160BB0AC9C1CB74218E549825D8A3F74E16B76300140916E315ECC4D6B5E0C46BA05F93ACE8B0F137A0C42F3936E7E47845FBAB8DB1269E86CFEF857EB7EE346158B758A7A4066A7A253A9085C2AC226FE496F2EFE2CF067C13C9839601A27250E130BC216BDE08124B0115D98E60BC612739E4B864E03268FC00CF799582160955C7972D9000F9DD2C12D9F5B23738D349C4804FA1085666D9F43A7B69DF86F5147F280714BD41B730993A2CDB7DF66A797E98124284B20AE3EE3A40460C5571325C0624A5BA9ADC59832DCE1B37742BB16E0F79FEE5FE3DB8712DC939437CB919C388268B4B2792F08786779C64D5469076C79A5DD46CE41823738E00A5D8D1DE67DA58AF6B0D4599CCEE208ED0E556F87CF98509FE52D25C9A54CC003E442C417B45E3EFD144A4FB319A2EDEB6D8FDBE2048C2CC16BFCA986247BF696FE6C9E0023B3CE79004376685A9E81D7622924A1EF5E11FA365DA21F56C80EA6693B8F4B86EE4811AA7A5BCD46A827107C67&sign=78DD78BC69CECB26685C72E18126E9D4AD7E875A (Caused by NewConnectionError('<urllib3.connection.HTTPSConnection object at 0x7fe64f3ebfd0>: Failed to establish a new connection: [Errno 101] Network is unreachable'))
### 执行结果
- **登录状态**: 登录失败
- **签到结果**: 

## 账户3
登录过程出错: HTTPSConnectionPool(host='open.e.189.cn', port=443): Max retries exceeded with url: /api/logbox/oauth2/autoLogin.do?appId=cloud&version=v1.1&clientType=20010&format=redirect&paras=641CEDD0A1D1647D3B729C4C383E69DFD95F970648A2DC3C3FDE4737A2A16370AB8270246317B67C782E758483F0EB87E32833703CDA19934FAE23027544D9A5DA5B369C518C4AFB19B3DD4424E9F2036FA2654B76427881A2577D32C7B1EAB186EE5D67270916F51152C4A1C528A79858E7E1D2EAE8BBE6C7954A1700C5769AAADB32D5D38A8452B2F88DA6323E766AD39CDF1853651BB7A26F655E4DC10012CFC3418AE534A84AE43D7111BF8E7F40BED68D8437BEEFEFBF570A2B319B70FC842AF05B1160FAF93C527DE2138EA49BE0F7839EA818D06333273AE7114A58FB7596A49AAE2F207D5267187100767708C31F1A4F6DDA51B983D25DC10332261AC3E253EC7C4D236A5BE3BBCDF71FA2E19C079C2977BB864C9B815F326286470C57B2B0CA9AB3C5B5F34DF82EEF3387A37DF50E66205E611F47E4BB91AABCB37BA2DD43BDE41CF505D2832898675285EB5CF8BF69C8A872B978BB1EAB2B8418E00C0F3CDB441C5A64E74C4E26B478B2C77AB16DCB0FB7EBCC081395870256140D5272360FCC08942D5AF15F5E7AF6EDDECA43A968D68CD61978E4745715C0616DF0205B44E05542497E1CF0E455966FF032452E9F1DA5B381569C7A6825B11EADC98D7773AE0551D91910C8094D4B6C59DE8C7E23B9A7FD247AD8B915B22781F7279794C47FCF7550CFABAB811610769EF4CE9DF55623D8E41EBA64E6B53CFECECF562D887D09883B80DDD36BED6BDB7D484E56A0B2DA56C5&sign=5A3C273A6EF4FE7BB104B2BF490EEC6E46B7E5EC (Caused by NewConnectionError('<urllib3.connection.HTTPSConnection object at 0x7fe64f3d7ed0>: Failed to establish a new connection: [Errno 101] Network is unreachable'))
### 执行结果
- **登录状态**: 登录失败
- **签到结果**: 

---
## 执行统计
- **结束时间**: 2025-07-24 22:10:09
- **运行时长**: 819.83 秒

✅ **所有账户处理完成！**
