# 天翼云盘签到记录

[![签到状态](https://github.com/mfvi/189pan/actions/workflows/main.yml/badge.svg)](https://github.com/mfvi/189pan/actions/workflows/main.yml) [![项目主页](https://img.shields.io/badge/GitHub-项目主页-blue?logo=github)](https://github.com/mfvi/189pan)

**最后更新:** 2025-07-11 11:17:44 CST

## 快速导航

- 🔄 [查看Action运行记录](https://github.com/mfvi/189pan/actions)
- 📋 [查看最新运行](https://github.com/mfvi/189pan/actions/runs/16210982021)
- 🏠 [返回项目主页](https://github.com/mfvi/189pan)
- ⚙️ [手动触发签到](https://github.com/mfvi/189pan/actions/workflows/main.yml)

## 签到详情

# 天翼云盘自动签到抽奖程序

## 执行概览
- **启动时间**: 2025-07-11 11:17:44
- **账户数量**: 3 个

## 账户1
登录过程出错: HTTPSConnectionPool(host='open.e.189.cn', port=443): Max retries exceeded with url: /api/logbox/oauth2/autoLogin.do?appId=cloud&version=v1.1&clientType=20010&format=redirect&paras=5719A8D682002E5F1E56A4C49ECA13AF717502986BE7306EBDA4E09E0783F795616512D9B71040318CAF087AA9E6A6BF4163FE3ACB9CC9E41D86FED5BCCF32E502F6CC340411907F8A6A9A22138616FA1A467F334057734DFA63BC6FA4D0709184B05321FE470E64DCA7FC7717CC0B8C5CE9994BB752EA12EEFF358710402089CABEDD87E5E3D993DE6988D08717EAECE14F5B40F278039D2640A7FF75936758EBD2E0218C54DBED9C28956DCC0D6F6E64DF34F04C1DBE4A71696BF4995D48AE69539BDE839661A907BC5DB29D94FDCF35E0A0582BB8D87D44A4DA914C874DC93BB8867E1AB2AAD053BFFF06C0261EF6E448AB5EDF91E61579B99021A73656CD92974AFA39AA0974737694ED8B8B231FDF9734AE72C11EF1DA66BEC31680F73755AAD8DE53ED6C4AAB29C24AA61F638B8CEF9B1661E2F039F726F7CD3AF226D9ECC34E4F8143A2E44357C2DB7CE115763693156F4F0EB53598251D7873BECCEFC01AE1377EB74AAAFF329843D33E0DEECD00A0AF88CBD7ACAA5D62A4E9B9EA660B3D7C3D3E0254B3E92AACE1C91CFF926814116A4DAF7A48BBC0678103655956714C66330D2EB68934DD5DDA73D046EEC5BB6DCCCAB867DB7BED33B134B095DB06490F477EB14D3A5091E20F5F7C2D1437ED916FACBFBEAC2BF1B0DC54F1C2494CB52E6B10880741209110FD08B4757ECD55BF803ECD9D1FDC56089A6048E0B4AF7B7ED7DEB54CA35847BC17438FD1B67E2F82FE85BD8743&sign=BFC48FC4807514629F6C24A4EB516A592FC2AFC2 (Caused by NewConnectionError('<urllib3.connection.HTTPSConnection object at 0x7f0619a38ad0>: Failed to establish a new connection: [Errno 101] Network is unreachable'))
### 执行结果
- **登录状态**: 登录失败
- **签到结果**: 

## 账户2
登录过程出错: HTTPSConnectionPool(host='open.e.189.cn', port=443): Max retries exceeded with url: /api/logbox/oauth2/autoLogin.do?appId=cloud&version=v1.1&clientType=20010&format=redirect&paras=200E0E59C0DEBE0BF98AAC8051960A8F55790F5F0335CF378EF4B765EF7961DF3F8B629B314574C9DD7E5535C3D289952D3DF16A89F0D7AD02D1A238151BDB37024063D6A158F114EE81549FF327DD14D8D1DEF9A5D38EBA5084AAA9E7DD3BB68B4896722DEB3028906D1F3BBED08A2633901303CE3FD08234774F878C953C83EB8B22412434A060AD2B0D26C9AEFBBD4E6161F4CE691F55E8C06319A13EC81C7A2F2FCEF664695FA7054D0A74D889FBA689A98AA3EEC58AEC53043D3B107B2FD7D108F00B4AB736FF107C3690FB014C3E11CA47CD042AF935D9171E72329C266C2BE7C070C7BE992B0B82ABB9F3253C9B7059ECC8159462D7B9AC15DD927E246D56AEE9B9A0D05E367D17B05A6C3E9E0A9CA9612D74A3600BE9252AD34E8D81BA592145F435006A725C490CFED578570B882948BE410FDACB624F57D3F30D4A0D52E50396A53DF18D82C1677722D2E9558A434C96B04C21D53AC0BC754F81268ECCF7524CD8EEF21C04D6345B9172EAA48CDF07FF7CB77F849E9085263BACAD9B5669480398890E087EBE74330B49BDF5E7652C283C9A480A332E2A6A8AC18CE261E382EBDEA1F1B3E2FC8EA0BB96AED08E8CA8F856455D76DF6661F78A237D93B5FBC937C3DC61211041C8F8F8B48E82B4AFAB4379D5FD170B3D985DBE32969DA50871DA5EB901610C31302B5C6FE74A69D42B710ED30F88A63EE2927305E29D1B47BF94A9A395DFE895127B862843545F2BB9DFB85970&sign=2AF113A35C48EA2138A7B2D5B936593C4F3C2E6B (Caused by NewConnectionError('<urllib3.connection.HTTPSConnection object at 0x7f0619a40290>: Failed to establish a new connection: [Errno 101] Network is unreachable'))
### 执行结果
- **登录状态**: 登录失败
- **签到结果**: 

## 账户3
登录过程出错: HTTPSConnectionPool(host='open.e.189.cn', port=443): Max retries exceeded with url: /api/logbox/oauth2/autoLogin.do?appId=cloud&version=v1.1&clientType=20010&format=redirect&paras=99C9527721419E118FB5BCF01901E9690DEE33413792A51C09E31EEE472C8F6E9D33AAA6E97DB78E35121F50604DC216FEA33BDBB92D0FEDED4320486CE6585B1A94790FCB8AEE66CD4E3573016DEDFCD3BC5499800DCA8EA59468EB4FB139463BE426E3E14974DE73F14A210A48CF1A22002071BD661FA452E315B2CBE14FBF551D4102A41B5121C15BE13519D5E22F7E9C38188AE508C2E5A9A2D04A2BBFE87E526D652BA8CE3A033C0B632E6167C40536327E1AB3A1B71009CBEB4BF8205CA54350A94C973C392FBE990440655374D7CCDE624E09619FF7B367E8815438CEF34CEA6267706516FE634D3B64F8F4F9A91516A62F9DEE61CF45CE4153E7E7797F9254694E69554EE3CC507D54E921F8F9D45AECD3E0493F8F9E2485962C9F3D7009256C44450196C24B8FD8CD38CFB212D5068004D660205CC702D8E642083202233CE0FBA352E001672FDFF26759A1289D73CE2AFBB834A8C93E483372A8C0201DBC29E49441CF510338A5F27DEAB291248ABC7149A0F84D29C3B7775DCF8CE6A5D6CDCB760423759CFE84F19D78799C7074AED9BD59EEDAA0A1AA2910650070F11A07770998FE4ED5550ED248F15FF8C2396010826A5BF4E43ED102150B7178F0F51B721D6394CE6E998E57DFCB5238BF7EDC0595D1338E6BF26A80574BCD9F1095FBD6C6159DE75EA9044ABCF4814BF195373E61E0E67E9C7FE79C6515DE109A00718578CF39A068A7319EC418AC41F198E4872524C8&sign=A7497638901FE79AC17211DCD69FAC733314DBFC (Caused by NewConnectionError('<urllib3.connection.HTTPSConnection object at 0x7f0619a39d50>: Failed to establish a new connection: [Errno 101] Network is unreachable'))
### 执行结果
- **登录状态**: 登录失败
- **签到结果**: 

---
## 执行统计
- **结束时间**: 2025-07-11 11:31:22
- **运行时长**: 817.38 秒

✅ **所有账户处理完成！**
