# 天翼云盘签到记录

[![签到状态](https://github.com/mfvi/189pan/actions/workflows/main.yml/badge.svg)](https://github.com/mfvi/189pan/actions/workflows/main.yml) [![项目主页](https://img.shields.io/badge/GitHub-项目主页-blue?logo=github)](https://github.com/mfvi/189pan)

**最后更新:** 2025-10-04 10:38:43 CST

## 快速导航

- 🔄 [查看Action运行记录](https://github.com/mfvi/189pan/actions)
- 📋 [查看最新运行](https://github.com/mfvi/189pan/actions/runs/18238430911)
- 🏠 [返回项目主页](https://github.com/mfvi/189pan)
- ⚙️ [手动触发签到](https://github.com/mfvi/189pan/actions/workflows/main.yml)

## 签到详情

# 天翼云盘自动签到抽奖程序

## 执行概览
- **启动时间**: 2025-10-04 10:38:43
- **账户数量**: 3 个

## 账户1
登录过程出错: HTTPSConnectionPool(host='open.e.189.cn', port=443): Max retries exceeded with url: /api/logbox/oauth2/autoLogin.do?appId=cloud&version=v1.1&clientType=20010&format=redirect&paras=AA1A66B444219E0AA409AD68BF6EB4EDF3EEA17DBB473C1BE574C4B124BD155DBDB9A3D87EFA6C5E0F685687A1838D96484F35219EADE1DCABF2FC953B798354B702DBFF76C85C7B037E449B490230D9510B3595FB51AD51DBC0269B16110F69D1708F8771AD8193E5BFB7A44656653C8B9EFB3025BCC4C1C4F890D4437EF4D67C2AE1C3C64BF5285A61D4B90BDEAB6D9775201A776CB5E5A8DAC1C396184B1E4A7BDF2582CAFF459CDD22E22ADABAEABD601331FAF8393E8415A92EF32CF7A6EFF206C677F07EFC621F20885C327AF507F4F5FEDE61BD4C0ED62E789C9F4FD4372D7AC7D17E8D2432276A5EC98911C10332D10A6588E008C56C30F21D23439D1FAE3796BB04EADC67E796CA5B340E7FC4EB60A08C72C482E3316AC65EFD08B85E4791BBA83B826A835DD7A2FE539128C9DD44C3886F0B2BD2C631969A49167080B5D5081FDC3876324C5D13A889E1D52386FDDF20932EEA4CA695D2D5BD30829E1CCE582762612E6C1FE769F24983C5C2278837956E7474C901FE73027EFE7B749C7FEBEB7302932BA6BF073DDA8E8EDFDD78C50B288746F454105E52F16DEA794FA7958B5476D900E50D9C30569E9D0210F935387ECB3F0EDD1B4FFCFDAA41645FCB7ED86629CABC7E1A7849A7C2A17DA4BE8012E20F947776D8CB22F34DA0BD0050C5064DA4A201380B51C5F4D0A0EE06296832F61D7A1FD52696132AA71067BE2CEBC5F1156A4ADDDDDFB5FAD77BFBCAFF1E795C8FD8&sign=36DDEA65525C80E5A23866BBD47CAB79283B5270 (Caused by NewConnectionError('<urllib3.connection.HTTPSConnection object at 0x7f12896a0e50>: Failed to establish a new connection: [Errno 101] Network is unreachable'))
### 执行结果
- **登录状态**: 登录失败
- **签到结果**: 

## 账户2
登录过程出错: HTTPSConnectionPool(host='open.e.189.cn', port=443): Max retries exceeded with url: /api/logbox/oauth2/autoLogin.do?appId=cloud&version=v1.1&clientType=20010&format=redirect&paras=826315D9503EBB0F0319492D0869DB532E1109848DAAB13A674F3396EC405EE6F9ADC8FDECD92AB836D516C9E75367DDAE404E3825644D6E814F2BF9BC58A8C692849E382931B312B48F492F86BC7D8AA9ADA0F91F9A66CCACB6CDC2EFD5DE642431B6EA742B6453A253D028DFB298ECB70114A8FB2DC9DB3F2308E9A87A51CFAB5898830FBB6EE922316A238C89B34F0409EA902B4324AC10E194BD68FCABAF1421A833AFE797E9B470CBF949879E6F61799F4D9E53B6F47755B5205CFF9CC88883A3506EE05EC63DE6C97F71EE8C3425423F430EF44FB570532755F63B1610AC6708AE5640513CF1F2A23BD7B39ECC1DF6204536121A5B176741231C4BF31942686CB0A7B86FB2C38EC58CD54AA55A0D42D15E954BC01A18AB115BB51C0251CDAC82643843BC7DD07EB0B3DABBFFFB97C38C480F7266040D9BD14ACA5283B531173740246D2839FF9636172B90812AC77B5A59D28D248ED5ACCF0B0929C008E471C66D508B0E327873E0BF4E2859EA80583FEB0C523EFECA7B081F2CD25393D9C842DEF4BB5795EA7AE641CDADA67234CCF21C1998E4032ACB0F10FEAEBF6360F27A5753F5A7C2C06B3AD4339A7D7782FF31E7C846DD07BE527850D535A05AEB1869279883193571FD527B237E7AA79DBF57DDE4345594AF84462AD2EA3856C2E322346F75C1EFA8252382BA1D786495EFF2931BFC94B30102F5FCD119C0094C17A2E1A4D4D7C4ADF7FA5E8248F1BCBF5E856E20E0CB85&sign=4F671F8165EA91C077D692014683A99EB04CD12A (Caused by NewConnectionError('<urllib3.connection.HTTPSConnection object at 0x7f12896ac610>: Failed to establish a new connection: [Errno 101] Network is unreachable'))
### 执行结果
- **登录状态**: 登录失败
- **签到结果**: 

## 账户3
登录过程出错: HTTPSConnectionPool(host='open.e.189.cn', port=443): Max retries exceeded with url: /api/logbox/oauth2/autoLogin.do?appId=cloud&version=v1.1&clientType=20010&format=redirect&paras=1CA2FD061E74DAB7CD0EC0C2DF068714AA4EFF2E55DBC6C90039AC4D99BFE7ECFEB2B67B95D93A73067C89B7B61EDCD86930A2B7361BD27D75BA551AB994271838E4A08A6CD83D3716A11949C4EF194FAF54D3DDE91AC80CB5190E1A1E7FF9BE188D3B6D04210529233D49E06CF98B2D036E5C9329A76096E018A993177A2C42E9F3112BBF555777F597F42EA8DFDC28606BF7D5ED58D7E739FAFEBB7D599D8FAFDB02DC9281F826E007C3E7E87D1C14DA6BE552B57DE09E652A4BD726D3FE9ABA44DD86B754A1F40ED1C6333583EAB92E99212F1E863766361EEAD33155B3EE592CF0E7F9ACC2A8233F0A0A5BCD6ABF726076C80014BDCFA5533E0B04EA60CB2EA9A4E6642EE5B2C2F85F5DA7863ABBC11C04632F6C7BE9E4834DC24CAB60C85B31BFC738329EB45BAAAECD69EE9FB05CBE2FE005E066D5FDD731CCE2631EB71C539338BD1E139586497F76E3EB2C5380886200C84FE25A5335BDC55B7AEAA6C0BAFF40487129C089151235AA0112909ADB17BA64A4C607C28FE0D238E9CAF953EB7AD3C142258F304DAD6B334FB42498A6CF010507ED9FA950F3A99EC577F1BEDEFFBA232E6BBDE2C307F1175C92A0FB49D066DE66C3A19E2A148907ECB8B83C15B4DA36813EFBCA86EF31C61446894A6788DE1CA24EAB2CE43175AA75A1E407D010E7C69A37AC08D2C61CF3FD2A8FB5515DF14AE55B77E404F8EA9E2C4C80D5DDB06718337E942B1C4E1B973ACA974AEB59FA5B77AF89&sign=2C9EEA0BBB9188D1520B1B3AB07C6C01B0C85424 (Caused by NewConnectionError('<urllib3.connection.HTTPSConnection object at 0x7f12896974d0>: Failed to establish a new connection: [Errno 101] Network is unreachable'))
### 执行结果
- **登录状态**: 登录失败
- **签到结果**: 

---
## 执行统计
- **结束时间**: 2025-10-04 10:52:14
- **运行时长**: 811.01 秒

✅ **所有账户处理完成！**
